<!-- Authors: Inkyu and Jemin 5/Aug/2019 -->
<!-- contact:enddl22@gmail.com -->

<?xml version="1.0"?>
<robot name="Cartpole">
  <link name="world">  </link>

  <joint name="world_to_sliderBar" type="fixed">
    <axis xyz="0 0 0"/>
    <origin xyz="0.0 0.0 1.0"/>
    <parent link="world"/>
    <child link="sliderBar"/>
  </joint>

  <link name="sliderBar">
    <visual>
      <geometry>
        <cylinder radius="0.05" length="40"/>
      </geometry>
      <origin xyz="0 0 0" rpy="0 1.5708 0"/>
    </visual>
    <inertial>
      <mass value="0"/>
      <inertia ixx="1.0" ixy="0.0" ixz="0.0" iyy="1.0" iyz="0.0" izz="1.0"/>
    </inertial>
  </link>

  <link name="slider">
    <inertial>
      <mass value="2"/>
      <inertia ixx="2.0" ixy="0.0" ixz="0.0" iyy="1.0" iyz="0.0" izz="2.0"/>
    </inertial>
    <visual>
      <geometry>
        <box size="0.3 0.3 0.2"/>
      </geometry>
      <origin xyz="0 0 0"/>
    </visual>
  </link>

  <link name="rod">
    <inertial>
      <origin xyz="0 0 0.5"/>
      <mass value="5"/>
      <inertia ixx="1.0" ixy="0.0" ixz="0.0" iyy="1.0" iyz="0.0" izz="1.0"/>
    </inertial>
    <visual>
      <geometry>
        <cylinder radius="0.04" length="0.8"/>
      </geometry>
      <origin rpy="0 0 0" xyz="0 0 0.5"/>
    </visual>
  </link>

  <joint name="slider" type="prismatic">
    <axis xyz="1 0 0"/>
    <origin xyz="0.0 0.0 0.0"/>
    <parent link="sliderBar"/>
    <child link="slider"/>
    <limit effort="1000.0" lower="-15" upper="15"/>
    <dynamics spring_mount="0.5" stiffness="150.0" damping="20."/>
  </joint>

  <joint name="bar_revolute" type="revolute">
    <axis xyz="0 1 0"/>
    <parent link="slider"/>
    <child link="rod"/>
    <origin xyz="0.0 0.0 0"/>
    <limit effort="80" lower="-6.28" upper="6.28"/>
    <dynamics spring_mount="0.5" stiffness="150.0" damping="20."/>
  </joint>

</robot>
