<?xml version="1.0" encoding="utf-8"?>
<!-- =================================================================================== -->
<!-- |    This document was autogenerated by xacro from anymal_c.urdf.xacro            | -->
<!-- |    EDITING THIS FILE BY HAND IS NOT RECOMMENDED                                 | -->
<!-- =================================================================================== -->
<!-- This file contains the description of the ANYmal robot. -->
<robot name="anymal" xmlns:xacro="http://www.ros.org/wiki/xacro">
    <gazebo>
        <plugin filename="libanymal_gazebo.so" name="gazebo_ros_control">
            <robotNamespace>anymal</robotNamespace>
            <!-- Currently unused -->
            <robotDescription>anymal_description</robotDescription>
            <robotBaseLink>base</robotBaseLink>
        </plugin>
    </gazebo>
    <!-- [kg * m^2] -->
    <!-- Base link -->
    <link name="base">
        <!--      <visual>-->
        <!--        <origin xyz="0 0 0" rpy="0 0 0"/>-->
        <!--        <geometry>-->
        <!-- <mesh
                filename="package://anymal_c_description/urdf/base/3_0_mesh.dae"
                scale="${anymal_meshes_scale}"/> -->
        <!--        </geometry>-->
        <!--      </visual>-->
    </link>
    <!-- Fixed joint to add dummy inertia link -->
    <joint name="base_to_base_inertia" type="fixed">
        <parent link="base"/>
        <child link="base_inertia"/>
        <origin rpy="0 0 0" xyz="0 0 0"/>
    </joint>
    <!-- Dummy inertia link, because KDL cannot have inertia on the base link -->
    <link name="base_inertia">
        <inertial>
            <origin rpy="0 0 0" xyz="-0.021735324742 -0.001486870654 0.024282211582"/>
            <mass value="8.1"/>
            <inertia ixx="0.0373546074128" ixy="-0.00065609405117" ixz="0.00018657925965" iyy="0.746506907991" iyz="-0.000230891041262" izz="0.747061691514"/>
        </inertial>
    </link>
    <!-- Fixed joint to add docking socket -->
    <joint name="base_to_docking_socket" type="fixed">
        <parent link="base"/>
        <child link="docking_socket"/>
        <origin rpy="0 0 0" xyz="0.343 0.0 -0.08"/>
    </joint>
    <!-- Docking socket link -->
    <link name="docking_socket"/>
    <link name="imu_link">
        <visual>
            <origin rpy="0 0 0" xyz="0 0 0.011"/>
            <geometry>
                <box size="0.058 0.058 0.022"/>
            </geometry>
            <material name="orange"/>
        </visual>
<!--        <collision>-->
<!--            <origin rpy="0 0 0" xyz="0 0 0.011"/>-->
<!--            <geometry>-->
<!--                <box size="0.058 0.058 0.022"/>-->
<!--            </geometry>-->
<!--        </collision>-->
        <inertial>
            <mass value="0.05"/>
            <origin xyz="0 0 0"/>
            <inertia ixx="1.60333333333e-05" ixy="0.0" ixz="0.0" iyy="2.80333333333e-05" iyz="0.0" izz="1.60333333333e-05"/>
        </inertial>
    </link>
    <joint name="imu_joint" type="fixed">
        <parent link="base"/>
        <child link="imu_link"/>
        <origin rpy="0 0 0" xyz="0.379624 0.00445 0.0563"/>
    </joint>
    <gazebo reference="imu_link">
        <material>Gazebo/Orange</material>
        <mu1>0.8</mu1>
        <mu2>0.8</mu2>
    </gazebo>
    <gazebo reference="imu_joint">
    </gazebo>
    <gazebo>
        <plugin filename="libany_hector_gazebo_ros_imu.so" name="imu_plugin">
            <robotNamespace>sensors</robotNamespace>
            <bodyName>imu_link</bodyName>
            <frameId>imu_link</frameId>
            <topicName>imu</topicName>
            <biasTopicName>imu/bias</biasTopicName>
            <serviceName>imu/calibrate</serviceName>
            <updateRate>400</updateRate>
        </plugin>
    </gazebo>
    <!-- [kg * m^2] -->
    <!-- [m] -->
    <!-- Camera joint -->
    <!-- Is located between the two back screw holes at ground level. -->
    <joint name="base_to_realsense_d435_left_camera" type="fixed">
        <parent link="base"/>
        <child link="realsense_d435_left_camera"/>
        <origin rpy="0.0 0.523598775598 1.57079632679" xyz="0.0 0.0722 0.0324"/>
    </joint>
    <!-- Camera link -->
    <link name="realsense_d435_left_camera">
        <!--      <visual>-->
        <!--        <origin xyz="0.0 0.0 0.0" rpy="0 0 0"/>-->
        <!--        <geometry>-->
        <!--          <mesh filename="package://any_description/urdf/sensors/realsense/d435/realsense_d435.dae" scale=".001 .001 .001"/>-->
        <!--        </geometry>-->
        <!--      </visual>-->
        <inertial>
            <origin rpy="0 0 0" xyz="0.0642 -0.0102 0.0033"/>
            <mass value="0.2"/>
            <inertia ixx="0.002318" ixy="-1e-06" ixz="9e-06" iyy="0.00206" iyz="0.000333" izz="0.002439"/>
        </inertial>
    </link>
    <!-- Camera parent joint -->
    <!-- Frame lies on the left ir camera according to realsense2_camera urdf. -->
    <joint name="realsense_d435_left_camera_to_camera_parent" type="fixed">
        <parent link="realsense_d435_left_camera"/>
        <child link="realsense_d435_left_camera_parent"/>
        <origin rpy="0.0 0.0 0.0" xyz="0.0255 0.0175 0.0"/>
    </joint>
    <!-- Camera parent link -->
    <link name="realsense_d435_left_camera_parent"/>
    <!-- simulation or bagfile_is_played -->
    <!-- simulation -->
    <!-- [kg * m^2] -->
    <!-- [m] -->
    <!-- Camera joint -->
    <!-- Is located between the two back screw holes at ground level. -->
    <joint name="base_to_realsense_d435_right_camera" type="fixed">
        <parent link="base"/>
        <child link="realsense_d435_right_camera"/>
        <origin rpy="0.0 0.523598775598 -1.57079632679" xyz="0.0 -0.0722 0.0324"/>
    </joint>
    <!-- Camera link -->
    <link name="realsense_d435_right_camera">
        <!--      <visual>-->
        <!--        <origin xyz="0.0 0.0 0.0" rpy="0 0 0"/>-->
        <!--        <geometry>-->
        <!--          <mesh filename="package://any_description/urdf/sensors/realsense/d435/realsense_d435.dae" scale=".001 .001 .001"/>-->
        <!--        </geometry>-->
        <!--      </visual>-->
        <inertial>
            <origin rpy="0 0 0" xyz="0.0642 -0.0102 0.0033"/>
            <mass value="0.2"/>
            <inertia ixx="0.002318" ixy="-1e-06" ixz="9e-06" iyy="0.00206" iyz="0.000333" izz="0.002439"/>
        </inertial>
    </link>
    <!-- Camera parent joint -->
    <!-- Frame lies on the left ir camera according to realsense2_camera urdf. -->
    <joint name="realsense_d435_right_camera_to_camera_parent" type="fixed">
        <parent link="realsense_d435_right_camera"/>
        <child link="realsense_d435_right_camera_parent"/>
        <origin rpy="0.0 0.0 0.0" xyz="0.0255 0.0175 0.0"/>
    </joint>
    <!-- Camera parent link -->
    <link name="realsense_d435_right_camera_parent"/>
    <!-- simulation or bagfile_is_played -->
    <!-- simulation -->
    <!-- [kg * m^2] -->
    <!-- [m] -->
    <!-- parent to cage joint, located between mounting plate on trunk and the cage -->
    <joint name="base_to_velodyne_cage" type="fixed">
        <parent link="base"/>
        <child link="velodyne_cage"/>
        <origin rpy="0 0 3.14159265359" xyz="-0.35 0.0 0.1"/>
    </joint>
    <!-- Velodyne cage link -->
    <link name="velodyne_cage">
        <!--      <visual>-->
        <!--        <origin xyz="0.0 0.0 0.0" rpy="0.0 0.0 0.0"/>-->
        <!--        <geometry>-->
        <!--          <mesh filename="package://anymal_c_description/urdf/sensors/velodyne/velodyne_cage.dae" scale="1.0 1.0 1.0"/>          </geometry>-->
        <!--      </visual>-->
        <!-- temporary visual, copied collision body -->
        <visual>
            <origin rpy="0 0 0" xyz="0 0 0.06"/>
            <geometry>
                <cylinder length="0.12" radius="0.07"/>
            </geometry>
        </visual>
        <collision>
            <origin rpy="0 0 0" xyz="0 0 0.06"/>
            <geometry>
                <capsule length="0.12" radius="0.07"/>
            </geometry>
        </collision>
        <inertial>
            <origin rpy="0.0 0.0 0.0" xyz="0.0642 -0.0102 0.0033"/>
            <mass value="0.2"/>
            <inertia ixx="0.002318" ixy="-1e-06" ixz="9e-06" iyy="0.00206" iyz="0.000333" izz="0.002439"/>
        </inertial>
    </link>
    <!-- [kg * m^2] -->
    <!-- parent to sensor joint -->
    <joint name="velodyne_cage_to_velodyne" type="fixed">
        <parent link="velodyne_cage"/>
        <child link="velodyne"/>
        <origin rpy="0.0 0.0 0.0" xyz="0.0 0.0 0.05"/>
    </joint>
    <!-- Velodyne sensor link -->
    <link name="velodyne">
        <inertial>
            <origin rpy="0.0 0.0 0.0" xyz="0.0642 -0.0102 0.0033"/>
            <mass value="0.5"/>
            <inertia ixx="0.002318" ixy="-1e-06" ixz="9e-06" iyy="0.00206" iyz="0.000333" izz="0.002439"/>
        </inertial>
        <!--      <visual>-->
        <!--        <origin xyz="0 0 0.0" />-->
        <!--        <geometry>-->
        <!--          <mesh filename="package://anymal_c_description/urdf/sensors/velodyne/velodyne.dae" />-->
        <!--        </geometry>-->
        <!--      </visual>-->
    </link>
    <!-- simulation -->
    <!-- [m] -->
    <!-- measured -->
    <!-- Fixed joint base shell -->
    <joint name="base_shell" type="fixed">
        <parent link="base"/>
        <child link="shell"/>
        <origin rpy="0 0 0" xyz="0 0 0"/>
    </joint>
    <!-- Shell link -->
    <link name="shell">
        <visual>
            <origin rpy="0 0 0" xyz="0 0 0"/>
            <geometry>
                <mesh filename="3_0_collision.dae" scale="1.0 1.0 1.0"/>
            </geometry>
        </visual>
        <collision>
            <origin rpy="0 0 0" xyz="0 0 0"/>
            <geometry>
                <box size="0.58 0.14 0.18"/>
            </geometry>
        </collision>
        <collision>
            <origin rpy="0 1.57079632679 0" xyz="0.2175 0.07 0"/>
            <geometry>
                <cylinder length="0.145" radius="0.09"/>
            </geometry>
        </collision>
        <collision>
            <origin rpy="0 1.57079632679 0" xyz="-0.2175 0.07 0"/>
            <geometry>
                <cylinder length="0.145" radius="0.09"/>
            </geometry>
        </collision>
        <collision>
            <origin rpy="0 1.57079632679 0" xyz="0.2175 -0.07 0"/>
            <geometry>
                <cylinder length="0.145" radius="0.09"/>
            </geometry>
        </collision>
        <collision>
            <origin rpy="0 1.57079632679 0" xyz="-0.2175 -0.07 0"/>
            <geometry>
                <cylinder length="0.145" radius="0.09"/>
            </geometry>
        </collision>
        <inertial>
            <origin rpy="0 0 0" xyz="0.001601658696 4.994078e-06 -0.053989505466"/>
            <mass value="1.268141902"/>
            <inertia ixx="0.0135322195912" ixy="-4.331264849e-06" ixz="0.000309123980027" iyy="0.0696430373562" iyz="-5.70632185e-07" izz="0.0735432141695"/>
        </inertial>
        <!-- Shell self filtering -->
        <self_filter>
            <origin rpy="0 0 0" xyz="0 0 0"/>
            <geometry>
                <box size="1.05 0.5 0.25"/>
            </geometry>
        </self_filter>
    </link>
    <!-- [kg * m^2] -->
    <!-- Fixed joint base battery -->
    <joint name="base_battery" type="fixed">
        <parent link="base"/>
        <child link="battery"/>
        <origin rpy="0 0 0" xyz="0 0 0"/>
    </joint>
    <!-- Shell link -->
    <link name="battery">
        <!--      <visual>-->
        <!--        <origin xyz="0 0 0" rpy="0 0 0"/>-->
        <!--       <geometry>-->
        <!--          <mesh-->
        <!--            filename="package://anymal_c_description/urdf/battery/3_0_mesh.dae"-->
        <!--            scale="${anymal_meshes_scale}"/>-->
        <!--        </geometry>-->
        <!--      </visual>-->
        <inertial>
            <origin rpy="0 0 0" xyz="-0.002960176299 -0.000123548844 -0.029760061761"/>
            <mass value="5.55"/>
            <inertia ixx="0.00745552667311" ixy="-0.000137110335303" ixz="0.000113360685966" iyy="0.0789745608826" iyz="1.220264954e-06" izz="0.081437267966"/>
        </inertial>
    </link>
    <!-- [m] -->
    <!-- measured -->
    <!-- Fixed joint base face -->
    <joint name="base_face_front" type="fixed">
        <parent link="base"/>
        <child link="face_front"/>
        <origin rpy="0 0 -0.0" xyz="0.475 0 0"/>
    </joint>
    <!-- Shell link -->
    <link name="face_front">
        <visual>
            <origin rpy="0 0 0" xyz="0 0 0"/>
            <geometry>
                <mesh filename="3_0_simple_mesh.dae" scale="1.0 1.0 1.0"/>
            </geometry>
        </visual>
        <collision>
            <origin rpy="0 0 0" xyz="0 0 0"/>
            <geometry>
                <box size="0.11 0.14 0.18"/>
            </geometry>
        </collision>
        <collision>
            <origin rpy="0 1.57079632679 0" xyz="0 0.07 0"/>
            <geometry>
                <cylinder length="0.11" radius="0.09"/>
            </geometry>
        </collision>
        <collision>
            <origin rpy="0 1.57079632679 0" xyz="0 -0.07 0"/>
            <geometry>
                <cylinder length="0.11" radius="0.09"/>
            </geometry>
        </collision>
        <inertial>
            <origin rpy="0 0 0" xyz="0.058640885474 5.7767683e-05 0.006500935099"/>
            <mass value="0.3"/>
            <inertia ixx="0.00353942466306" ixy="6.9508982e-07" ixz="8.5674409639e-05" iyy="0.000912856093445" iyz="3.44298293e-07" izz="0.00305824458528"/>
        </inertial>
    </link>
    <!-- [kg * m^2] -->
    <!-- [m] -->
    <!-- Camera joint -->
    <!-- Is located between the two back screw holes at ground level. -->
    <joint name="face_front_to_realsense_d435_front_camera" type="fixed">
        <parent link="face_front"/>
        <child link="realsense_d435_front_camera"/>
        <origin rpy="0.0 0.523598775598 0" xyz="0.041 0.0 -0.022"/>
    </joint>
    <!-- Camera link -->
    <link name="realsense_d435_front_camera">
        <!--      <visual>-->
        <!--        <origin xyz="0.0 0.0 0.0" rpy="0 0 0"/>-->
        <!--        <geometry>-->
        <!--          <mesh filename="package://any_description/urdf/sensors/realsense/d435/realsense_d435.dae" scale=".001 .001 .001"/>-->
        <!--        </geometry>-->
        <!--      </visual>-->
        <inertial>
            <origin rpy="0 0 0" xyz="0.0642 -0.0102 0.0033"/>
            <mass value="0.2"/>
            <inertia ixx="0.002318" ixy="-1e-06" ixz="9e-06" iyy="0.00206" iyz="0.000333" izz="0.002439"/>
        </inertial>
    </link>
    <!-- Camera parent joint -->
    <!-- Frame lies on the left ir camera according to realsense2_camera urdf. -->
    <joint name="realsense_d435_front_camera_to_camera_parent" type="fixed">
        <parent link="realsense_d435_front_camera"/>
        <child link="realsense_d435_front_camera_parent"/>
        <origin rpy="0.0 0.0 0.0" xyz="0.0255 0.0175 0.0"/>
    </joint>
    <!-- Camera parent link -->
    <link name="realsense_d435_front_camera_parent"/>
    <!-- simulation or bagfile_is_played -->
    <!-- simulation -->
    <!-- [kg * m^2] -->
    <!-- [m] -->
    <!-- Camera joint -->
    <!-- Is located in the center of the mounting points. -->
    <joint name="face_front_to_blackfly_front_camera" type="fixed">
        <parent link="face_front"/>
        <child link="blackfly_front_camera"/>
        <origin rpy="0 0 0" xyz="0.071 0.0 0.022"/>
    </joint>
    <!-- Camera link -->
    <link name="blackfly_front_camera">
        <!--      <visual>-->
        <!--        <origin xyz="0.0 0.0 0.0" rpy="0 0 0"/>-->
        <!--        <geometry>-->
        <!--          <mesh filename="package://anymal_c_description/urdf/sensors/blackfly/.dae" scale="1.0 1.0 1.0"/>-->
        <!--        </geometry>-->
        <!--      </visual>-->
        <inertial>
            <origin rpy="0 0 0" xyz="0.0642 -0.0102 0.0033"/>
            <mass value="0.1"/>
            <inertia ixx="0.002318" ixy="-1e-06" ixz="9e-06" iyy="0.00206" iyz="0.000333" izz="0.002439"/>
        </inertial>
    </link>
    <!-- Camera parent joint -->
    <joint name="blackfly_front_camera_to_camera_parent" type="fixed">
        <parent link="blackfly_front_camera"/>
        <child link="blackfly_front_camera_parent"/>
        <origin rpy="-1.57079632679 0.0 -1.57079632679" xyz="0.0 0.0 0.0"/>
    </joint>
    <!-- Camera parent link -->
    <link name="blackfly_front_camera_parent"/>
    <!-- simulation -->
    <!-- [m] -->
    <!-- measured -->
    <!-- Fixed joint base face -->
    <joint name="base_face_rear" type="fixed">
        <parent link="base"/>
        <child link="face_rear"/>
        <origin rpy="0 0 3.14159265359" xyz="-0.475 0 0"/>
    </joint>
    <!-- Shell link -->
    <link name="face_rear">
        <visual>
            <origin rpy="0 0 0" xyz="0 0 0"/>
            <geometry>
                <mesh filename="3_0_simple_mesh.dae" scale="1.0 1.0 1.0"/>
            </geometry>
        </visual>
        <collision>
            <origin rpy="0 0 0" xyz="0 0 0"/>
            <geometry>
                <box size="0.11 0.14 0.18"/>
            </geometry>
        </collision>
        <collision>
            <origin rpy="0 1.57079632679 0" xyz="0 0.07 0"/>
            <geometry>
                <cylinder length="0.11" radius="0.09"/>
            </geometry>
        </collision>
        <collision>
            <origin rpy="0 1.57079632679 0" xyz="0 -0.07 0"/>
            <geometry>
                <cylinder length="0.11" radius="0.09"/>
            </geometry>
        </collision>
        <inertial>
            <origin rpy="0 0 0" xyz="0.058640885474 5.7767683e-05 0.006500935099"/>
            <mass value="0.3"/>
            <inertia ixx="0.00353942466306" ixy="6.9508982e-07" ixz="8.5674409639e-05" iyy="0.000912856093445" iyz="3.44298293e-07" izz="0.00305824458528"/>
        </inertial>
    </link>
    <!-- [kg * m^2] -->
    <!-- [m] -->
    <!-- Camera joint -->
    <!-- Is located between the two back screw holes at ground level. -->
    <joint name="face_rear_to_realsense_d435_rear_camera" type="fixed">
        <parent link="face_rear"/>
        <child link="realsense_d435_rear_camera"/>
        <origin rpy="0.0 0.523598775598 0" xyz="0.041 0.0 -0.022"/>
    </joint>
    <!-- Camera link -->
    <link name="realsense_d435_rear_camera">
        <!--      <visual>-->
        <!--        <origin xyz="0.0 0.0 0.0" rpy="0 0 0"/>-->
        <!--        <geometry>-->
        <!--          <mesh filename="package://any_description/urdf/sensors/realsense/d435/realsense_d435.dae" scale=".001 .001 .001"/>-->
        <!--        </geometry>-->
        <!--      </visual>-->
        <inertial>
            <origin rpy="0 0 0" xyz="0.0642 -0.0102 0.0033"/>
            <mass value="0.2"/>
            <inertia ixx="0.002318" ixy="-1e-06" ixz="9e-06" iyy="0.00206" iyz="0.000333" izz="0.002439"/>
        </inertial>
    </link>
    <!-- Camera parent joint -->
    <!-- Frame lies on the left ir camera according to realsense2_camera urdf. -->
    <joint name="realsense_d435_rear_camera_to_camera_parent" type="fixed">
        <parent link="realsense_d435_rear_camera"/>
        <child link="realsense_d435_rear_camera_parent"/>
        <origin rpy="0.0 0.0 0.0" xyz="0.0255 0.0175 0.0"/>
    </joint>
    <!-- Camera parent link -->
    <link name="realsense_d435_rear_camera_parent"/>
    <!-- simulation or bagfile_is_played -->
    <!-- simulation -->
    <!-- [kg * m^2] -->
    <!-- [m] -->
    <!-- Camera joint -->
    <!-- Is located in the center of the mounting points. -->
    <joint name="face_rear_to_blackfly_rear_camera" type="fixed">
        <parent link="face_rear"/>
        <child link="blackfly_rear_camera"/>
        <origin rpy="0 0 0" xyz="0.071 0.0 0.022"/>
    </joint>
    <!-- Camera link -->
    <link name="blackfly_rear_camera">
        <!--      <visual>-->
        <!--        <origin xyz="0.0 0.0 0.0" rpy="0 0 0"/>-->
        <!--        <geometry>-->
        <!--          <mesh filename="package://anymal_c_description/urdf/sensors/blackfly/.dae" scale="1.0 1.0 1.0"/>-->
        <!--        </geometry>-->
        <!--      </visual>-->
        <inertial>
            <origin rpy="0 0 0" xyz="0.0642 -0.0102 0.0033"/>
            <mass value="0.1"/>
            <inertia ixx="0.002318" ixy="-1e-06" ixz="9e-06" iyy="0.00206" iyz="0.000333" izz="0.002439"/>
        </inertial>
    </link>
    <!-- Camera parent joint -->
    <joint name="blackfly_rear_camera_to_camera_parent" type="fixed">
        <parent link="blackfly_rear_camera"/>
        <child link="blackfly_rear_camera_parent"/>
        <origin rpy="-1.57079632679 0.0 -1.57079632679" xyz="0.0 0.0 0.0"/>
    </joint>
    <!-- Camera parent link -->
    <link name="blackfly_rear_camera_parent"/>
    <!-- simulation -->
    <!-- [rad] -->
    <!-- joint base HAA -->
    <joint name="base_LF_HAA" type="fixed">
        <parent link="base"/>
        <child link="LF_HAA"/>
        <origin rpy="0.174532925199 0 0.0" xyz="0.3 0.104 0.0"/>
    </joint>
    <!-- [m] -->
    <!-- [A] -->
    <!-- Drive link -->
    <link name="LF_HAA">
        <!--    <visual>-->
        <!--      <origin xyz="0 0 0" rpy="0 0 0"/>-->
        <!--      <geometry>-->
        <!--      <mesh filename="package://anymal_c_description/urdf/leg/drive/2_5_mesh.dae"-->
        <!--            scale="${anymal_meshes_scale}"/>-->
        <!--      </geometry>-->
        <!--    </visual>-->
        <!-- temporary visual, copied collision body -->
        <visual>
            <origin rpy="0 1.57079632679 0" xyz="-0.07 0 0"/>
            <geometry>
                <cylinder length="0.14" radius="0.05"/>
            </geometry>
        </visual>
        <inertial>
            <origin rpy="0 0 0" xyz="-0.051008462309 4.2382171e-05 0.001928394422"/>
            <mass value="1.371293164"/>
            <inertia ixx="0.00132750404318" ixy="2.667453e-07" ixz="-6.5578582056e-05" iyy="0.00197358077377" iyz="1.305902533e-06" izz="0.00183646051615"/>
        </inertial>
    </link>
    <!-- joint Drive output -->
    <joint name="LF_HAA" type="revolute">
        <parent link="LF_HAA"/>
        <child link="LF_HIP"/>
        <origin rpy="0 0 0" xyz="0 0 0"/>
        <axis xyz="1 0 0"/>
        <dynamics damping="0.0" friction="0.0"/>
    </joint>
    <!-- Drive output link -->
    <link name="LF_HIP">
        <inertial>
            <origin rpy="0 0 0" xyz="0 0 0"/>
            <mass value="0.001"/>
            <inertia ixx="0.000001" ixy="0.0" ixz="0.0" iyy="0.000001" iyz="0.0" izz="0.000001"/>
        </inertial>
    </link>
    <!-- [kg * m^2] -->
    <!-- joint HAA hip -->
    <joint name="LF_HIP_LF_hip_fixed" type="fixed">
        <parent link="LF_HIP"/>
        <child link="LF_hip_fixed"/>
        <origin rpy="-0.174532925199 0 0.0" xyz="0 0 0"/>
    </joint>
    <!-- Hip link -->
    <link name="LF_hip_fixed">
        <!--      <visual>-->
        <!--        <origin xyz="0 0 0" rpy="0 0 ${(front-1)*0.5*pi}"/>-->
        <!--        <geometry>-->
        <!--          <mesh-->
        <!--            filename="package://anymal_c_description/urdf/leg/hip/3_0_mesh${mirrored}.dae"-->
        <!--            scale="${anymal_meshes_scale}"/>-->
        <!--        </geometry>-->
        <!--      </visual>-->
        <inertial>
            <origin rpy="0 0 0" xyz="0.090762388354 0.000733055279 -0.001556575559"/>
            <mass value="0.490061659"/>
            <inertia ixx="0.00072708117274" ixy="-8.107655694e-06" ixz="2.1517369242e-05" iyy="0.00187018767039" iyz="2.508888647e-05" izz="0.00167883666103"/>
        </inertial>
    </link>
    <!-- [rad] -->
    <!-- joint hip HFE -->
    <joint name="LF_hip_fixed_LF_HFE" type="fixed">
        <parent link="LF_hip_fixed"/>
        <child link="LF_HFE"/>
        <origin rpy="0 0 1.57079632679" xyz="0.06 0.0701 0.0"/>
    </joint>
    <!-- [m] -->
    <!-- [A] -->
    <!-- Drive link -->
    <link name="LF_HFE">
        <!--    <visual>-->
        <!--      <origin xyz="0 0 0" rpy="0 0 0"/>-->
        <!--      <geometry>-->
        <!--      <mesh filename="package://anymal_c_description/urdf/leg/drive/2_5_mesh.dae"-->
        <!--            scale="${anymal_meshes_scale}"/>-->
        <!--      </geometry>-->
        <!--    </visual>-->
        <!-- temporary visual, copied collision body -->
        <visual>
            <origin rpy="0 1.57079632679 0" xyz="-0.05 0 0"/>
            <geometry>
                <cylinder length="0.10" radius="0.05"/>
            </geometry>
        </visual>
        <collision>
            <origin rpy="0 1.57079632679 0" xyz="-0.05 0 0"/>
            <geometry>
                <cylinder length="0.10" radius="0.05"/>
            </geometry>
        </collision>
        <inertial>
            <origin rpy="0 0 0" xyz="-0.051008462309 4.2382171e-05 0.001928394422"/>
            <mass value="1.371293164"/>
            <inertia ixx="0.00132750404318" ixy="2.667453e-07" ixz="-6.5578582056e-05" iyy="0.00197358077377" iyz="1.305902533e-06" izz="0.00183646051615"/>
        </inertial>
    </link>
    <!-- joint Drive output -->
    <joint name="LF_HFE" type="revolute">
        <parent link="LF_HFE"/>
        <child link="LF_THIGH"/>
        <origin rpy="0 0 0" xyz="0 0 0"/>
        <axis xyz="1 0 0"/>
        <dynamics damping="0.0" friction="0.0"/>
    </joint>
    <!-- Drive output link -->
    <link name="LF_THIGH">
        <inertial>
            <origin rpy="0 0 0" xyz="0 0 0"/>
            <mass value="0.001"/>
            <inertia ixx="0.000001" ixy="0.0" ixz="0.0" iyy="0.000001" iyz="0.0" izz="0.000001"/>
        </inertial>
    </link>
    <!-- [m] -->
    <!-- measured -->
    <!-- joint HFE thigh -->
    <joint name="LF_THIGH_LF_thigh_fixed" type="fixed">
        <parent link="LF_THIGH"/>
        <child link="LF_thigh_fixed"/>
        <origin rpy="0 0 -1.57079632679" xyz="0 0 0"/>
    </joint>
    <!-- Thigh link -->
    <link name="LF_thigh_fixed">
        <!--      <visual>-->
        <!--        <origin xyz="0 0 0" rpy="0 0 ${(front-1) * 0.5 * pi}"/>-->
        <!--        <geometry>-->
        <!--          <mesh -->
        <!--            filename="package://anymal_c_description/urdf/leg/thigh/3_0_mesh${mirrored}.dae"-->
        <!--            scale="${anymal_meshes_scale}"/>-->
        <!--        </geometry>-->
        <!--      </visual>-->
        <!-- temporary visual, copied collision body -->
        <visual>
            <origin rpy="1.57079632679 0 0" xyz="0 0.04 0"/>
            <geometry>
                <cylinder length="0.08" radius="0.065"/>
            </geometry>
        </visual>
        <visual>
            <origin rpy="0 0 0" xyz="0 0.03 -0.1413135"/>
            <geometry>
                <box size="0.075 0.06 0.282627"/>
            </geometry>
        </visual>
        <!-- Thigh collision -->
        <collision>
            <origin rpy="1.57079632679 0 0" xyz="0 0.04 0"/>
            <geometry>
                <cylinder length="0.08" radius="0.065"/>
            </geometry>
        </collision>
        <collision>
            <origin rpy="0 0 0" xyz="0 0.03 -0.1413135"/>
            <geometry>
                <box size="0.075 0.06 0.282627"/>
            </geometry>
        </collision>
        <inertial>
            <origin rpy="0 0 0" xyz="0.0127 0.0171 -0.1414"/>
            <mass value="0.977826611"/>
            <inertia ixx="0.014928" ixy="-8.8e-05" ixz="-0.001792" iyy="0.0158490785585" iyz="0.000654" izz="0.001794"/>
        </inertial>
    </link>
    <!-- [rad] -->
    <!-- joint thigh KFE -->
    <joint name="LF_thigh_fixed_LF_KFE" type="fixed">
        <parent link="LF_thigh_fixed"/>
        <child link="LF_KFE"/>
        <origin rpy="-0.261799387799 0 1.57079632679" xyz="0.0 0.086887 -0.282627"/>
    </joint>
    <!-- [m] -->
    <!-- [A] -->
    <!-- Drive link -->
    <link name="LF_KFE">
        <!--    <visual>-->
        <!--      <origin xyz="0 0 0" rpy="0 0 0"/>-->
        <!--      <geometry>-->
        <!--      <mesh filename="package://anymal_c_description/urdf/leg/drive/2_5_mesh.dae"-->
        <!--            scale="${anymal_meshes_scale}"/>-->
        <!--      </geometry>-->
        <!--    </visual>-->
        <!-- temporary visual, copied collision body -->
        <visual>
            <origin rpy="0 1.57079632679 0" xyz="-0.05 0 0"/>
            <geometry>
                <cylinder length="0.10" radius="0.05"/>
            </geometry>
        </visual>
        <collision>
            <origin rpy="0 1.57079632679 0" xyz="-0.05 0 0"/>
            <geometry>
                <cylinder length="0.10" radius="0.05"/>
            </geometry>
        </collision>
        <inertial>
            <origin rpy="0 0 0" xyz="-0.051008462309 4.2382171e-05 0.001928394422"/>
            <mass value="1.371293164"/>
            <inertia ixx="0.00132750404318" ixy="2.667453e-07" ixz="-6.5578582056e-05" iyy="0.00197358077377" iyz="1.305902533e-06" izz="0.00183646051615"/>
        </inertial>
    </link>
    <!-- joint Drive output -->
    <joint name="LF_KFE" type="revolute">
        <parent link="LF_KFE"/>
        <child link="LF_SHANK"/>
        <origin rpy="0 0 0" xyz="0 0 0"/>
        <axis xyz="1 0 0"/>
        <dynamics damping="0.0" friction="0.0"/>
    </joint>
    <!-- Drive output link -->
    <link name="LF_SHANK">
        <inertial>
            <origin rpy="0 0 0" xyz="0 0 0"/>
            <mass value="0.001"/>
            <inertia ixx="0.000001" ixy="0.0" ixz="0.0" iyy="0.000001" iyz="0.0" izz="0.000001"/>
        </inertial>
    </link>
    <!-- [m] -->
    <!-- measured -->
    <!-- joint KFE shank -->
    <joint name="LF_shank_LF_shank_fixed" type="fixed">
        <parent link="LF_SHANK"/>
        <child link="LF_shank_fixed"/>
        <origin rpy="0 0.261799387799 -1.57079632679" xyz="0 0 0"/>
    </joint>
    <!-- Shank link -->
    <link name="LF_shank_fixed">
        <!--      <visual>-->
        <!--        <origin xyz="0 0 0" rpy="0 0 ${(front-1)*0.5*pi}"/>-->
        <!--        <geometry>-->
        <!--          <mesh -->
        <!--            filename="package://anymal_c_description/urdf/leg/shank/3_0_mesh${mirrored}.dae"-->
        <!--            scale="${anymal_meshes_scale}"/>-->
        <!--        </geometry>-->
        <!--      </visual>-->
        <!-- temporary visual, copied collision body -->
        <visual>
            <origin rpy="1.57079632679 0 0" xyz="0 0.02 0"/>
            <geometry>
                <cylinder length="0.04" radius="0.06"/>
            </geometry>
        </visual>
        <visual>
            <origin rpy="1.57079632679 0 0" xyz="0.057499 0.02 0"/>
            <geometry>
                <box size="0.114998 0.0675 0.04"/>
            </geometry>
        </visual>
        <!-- Shank collision -->
        <collision>
            <origin rpy="1.57079632679 0 0" xyz="0 0.02 0"/>
            <geometry>
                <cylinder length="0.04" radius="0.06"/>
            </geometry>
        </collision>
        <collision>
            <origin rpy="1.57079632679 0 0" xyz="0.057499 0.02 0"/>
            <geometry>
                <box size="0.114998 0.0675 0.04"/>
            </geometry>
        </collision>
        <inertial>
            <origin rpy="0 0 0" xyz="0.032845496765 0.020087452943 0.000819464952"/>
            <mass value="0.3203472"/>
            <inertia ixx="0.000315561389972" ixy="-1.0430108417e-05" ixz="1.4120800915e-05" iyy="0.00107764668281" iyz="3.60309972e-07" izz="0.000870072710319"/>
        </inertial>
    </link>
    <!-- [m] -->
    <!-- joint shank foot -->
    <joint name="LF_shank_fixed_LF_FOOT" type="fixed">
        <parent link="LF_shank_fixed"/>
        <child link="LF_FOOT"/>
        <origin rpy="0 0 0" xyz="0.08748 0.006 -0.342504"/>
    </joint>
    <!-- Foot link -->
    <link name="LF_FOOT">
        <!--      <visual>-->
        <!--        <origin xyz="0 0 0" rpy="0 0 ${(front-1)*0.5*pi}"/>-->
        <!--        <geometry>-->
        <!--          <mesh-->
        <!--              filename="package://anymal_c_description/urdf/leg/foot/3_0_mesh.dae"-->
        <!--              scale="${anymal_meshes_scale}"/>-->
        <!--        </geometry>-->
        <!--      </visual>-->
        <!-- temporary visual, copied collision body -->
        <visual>
            <origin rpy="0 0 0" xyz="0 0 0.171252"/>
            <geometry>
                <cylinder length="0.22504" radius="0.0175"/>
            </geometry>
        </visual>
        <visual>
            <origin xyz="0 0 0.0225"/>
            <geometry>
                <sphere radius="0.03"/>
            </geometry>
        </visual>
        <!-- Adapter collision -->
        <collision>
            <origin rpy="0 0 0" xyz="0 0 0.171252"/>
            <geometry>
                <cylinder length="0.22504" radius="0.0175"/>
            </geometry>
        </collision>
        <!-- Foot collision -->
        <collision>
            <origin xyz="0 0 0.0225"/>
            <geometry>
                <sphere radius="0.03"/>
            </geometry>
        </collision>
        <inertial>
            <origin rpy="0 0 0" xyz="0.08640071854 4.566e-08 0.158952618655"/>
            <mass value="0.205145377"/>
            <inertia ixx="0.00315582473384" ixy="2.7197e-10" ixz="0.000388520744383" iyy="0.00316202017111" iyz="8.6741e-11" izz="8.1052626806e-05"/>
        </inertial>
    </link>
    <!-- Gazebo customization -->
    <gazebo reference="LF_FOOT">
        <kp>1000000.0</kp>
        <kd>100.0</kd>
        <mu1>0.8</mu1>
        <mu2>0.8</mu2>
    </gazebo>
    <!-- [rad] -->
    <!-- joint base HAA -->
    <joint name="base_RF_HAA" type="fixed">
        <parent link="base"/>
        <child link="RF_HAA"/>
        <origin rpy="-0.174532925199 0 0.0" xyz="0.3 -0.104 0.0"/>
    </joint>
    <!-- [m] -->
    <!-- [A] -->
    <!-- Drive link -->
    <link name="RF_HAA">
        <!--    <visual>-->
        <!--      <origin xyz="0 0 0" rpy="0 0 0"/>-->
        <!--      <geometry>-->
        <!--      <mesh filename="package://anymal_c_description/urdf/leg/drive/2_5_mesh.dae"-->
        <!--            scale="${anymal_meshes_scale}"/>-->
        <!--      </geometry>-->
        <!--    </visual>-->
        <!-- temporary visual, copied collision body -->
        <visual>
            <origin rpy="0 1.57079632679 0" xyz="-0.07 0 0"/>
            <geometry>
                <cylinder length="0.14" radius="0.05"/>
            </geometry>
        </visual>
        <inertial>
            <origin rpy="0 0 0" xyz="-0.051008462309 4.2382171e-05 0.001928394422"/>
            <mass value="1.371293164"/>
            <inertia ixx="0.00132750404318" ixy="2.667453e-07" ixz="-6.5578582056e-05" iyy="0.00197358077377" iyz="1.305902533e-06" izz="0.00183646051615"/>
        </inertial>
    </link>
    <!-- joint Drive output -->
    <joint name="RF_HAA" type="revolute">
        <parent link="RF_HAA"/>
        <child link="RF_HIP"/>
        <origin rpy="0 0 0" xyz="0 0 0"/>
        <axis xyz="1 0 0"/>
        <dynamics damping="0.0" friction="0.0"/>
    </joint>
    <!-- Drive output link -->
    <link name="RF_HIP">
        <inertial>
            <origin rpy="0 0 0" xyz="0 0 0"/>
            <mass value="0.001"/>
            <inertia ixx="0.000001" ixy="0.0" ixz="0.0" iyy="0.000001" iyz="0.0" izz="0.000001"/>
        </inertial>
    </link>
    <!-- [kg * m^2] -->
    <!-- joint HAA hip -->
    <joint name="RF_HIP_RF_hip_fixed" type="fixed">
        <parent link="RF_HIP"/>
        <child link="RF_hip_fixed"/>
        <origin rpy="0.174532925199 0 0.0" xyz="0 0 0"/>
    </joint>
    <!-- Hip link -->
    <link name="RF_hip_fixed">
        <!--      <visual>-->
        <!--        <origin xyz="0 0 0" rpy="0 0 ${(front-1)*0.5*pi}"/>-->
        <!--        <geometry>-->
        <!--          <mesh-->
        <!--            filename="package://anymal_c_description/urdf/leg/hip/3_0_mesh${mirrored}.dae"-->
        <!--            scale="${anymal_meshes_scale}"/>-->
        <!--        </geometry>-->
        <!--      </visual>-->
        <inertial>
            <origin rpy="0 0 0" xyz="0.090762388354 -0.000733055279 -0.001556575559"/>
            <mass value="0.490061659"/>
            <inertia ixx="0.00072708117274" ixy="8.107655694e-06" ixz="2.1517369242e-05" iyy="0.00187018767039" iyz="-2.508888647e-05" izz="0.00167883666103"/>
        </inertial>
    </link>
    <!-- [rad] -->
    <!-- joint hip HFE -->
    <joint name="RF_hip_fixed_RF_HFE" type="fixed">
        <parent link="RF_hip_fixed"/>
        <child link="RF_HFE"/>
        <origin rpy="0 0 -1.57079632679" xyz="0.06 -0.0701 0.0"/>
    </joint>
    <!-- [m] -->
    <!-- [A] -->
    <!-- Drive link -->
    <link name="RF_HFE">
        <!--    <visual>-->
        <!--      <origin xyz="0 0 0" rpy="0 0 0"/>-->
        <!--      <geometry>-->
        <!--      <mesh filename="package://anymal_c_description/urdf/leg/drive/2_5_mesh.dae"-->
        <!--            scale="${anymal_meshes_scale}"/>-->
        <!--      </geometry>-->
        <!--    </visual>-->
        <!-- temporary visual, copied collision body -->
        <visual>
            <origin rpy="0 1.57079632679 0" xyz="-0.05 0 0"/>
            <geometry>
                <cylinder length="0.10" radius="0.05"/>
            </geometry>
        </visual>
        <collision>
            <origin rpy="0 1.57079632679 0" xyz="-0.05 0 0"/>
            <geometry>
                <cylinder length="0.10" radius="0.05"/>
            </geometry>
        </collision>
        <inertial>
            <origin rpy="0 0 0" xyz="-0.051008462309 4.2382171e-05 0.001928394422"/>
            <mass value="1.371293164"/>
            <inertia ixx="0.00132750404318" ixy="2.667453e-07" ixz="-6.5578582056e-05" iyy="0.00197358077377" iyz="1.305902533e-06" izz="0.00183646051615"/>
        </inertial>
    </link>
    <!-- joint Drive output -->
    <joint name="RF_HFE" type="revolute">
        <parent link="RF_HFE"/>
        <child link="RF_THIGH"/>
        <origin rpy="0 0 0" xyz="0 0 0"/>
        <axis xyz="-1 0 0"/>
        <dynamics damping="0.0" friction="0.0"/>
    </joint>
    <!-- Drive output link -->
    <link name="RF_THIGH">
        <inertial>
            <origin rpy="0 0 0" xyz="0 0 0"/>
            <mass value="0.001"/>
            <inertia ixx="0.000001" ixy="0.0" ixz="0.0" iyy="0.000001" iyz="0.0" izz="0.000001"/>
        </inertial>
    </link>
    <!-- [m] -->
    <!-- measured -->
    <!-- joint HFE thigh -->
    <joint name="RF_THIGH_RF_thigh_fixed" type="fixed">
        <parent link="RF_THIGH"/>
        <child link="RF_thigh_fixed"/>
        <origin rpy="0 0 1.57079632679" xyz="0 0 0"/>
    </joint>
    <!-- Thigh link -->
    <link name="RF_thigh_fixed">
        <!--      <visual>-->
        <!--        <origin xyz="0 0 0" rpy="0 0 ${(front-1) * 0.5 * pi}"/>-->
        <!--        <geometry>-->
        <!--          <mesh -->
        <!--            filename="package://anymal_c_description/urdf/leg/thigh/3_0_mesh${mirrored}.dae"-->
        <!--            scale="${anymal_meshes_scale}"/>-->
        <!--        </geometry>-->
        <!--      </visual>-->
        <!-- temporary visual, copied collision body -->
        <visual>
            <origin rpy="1.57079632679 0 0" xyz="0 -0.04 0"/>
            <geometry>
                <cylinder length="0.08" radius="0.065"/>
            </geometry>
        </visual>
        <visual>
            <origin rpy="0 0 0" xyz="0 -0.03 -0.1413135"/>
            <geometry>
                <box size="0.075 0.06 0.282627"/>
            </geometry>
        </visual>
        <!-- Thigh collision -->
        <collision>
            <origin rpy="1.57079632679 0 0" xyz="0 -0.04 0"/>
            <geometry>
                <cylinder length="0.08" radius="0.065"/>
            </geometry>
        </collision>
        <collision>
            <origin rpy="0 0 0" xyz="0 -0.03 -0.1413135"/>
            <geometry>
                <box size="0.075 0.06 0.282627"/>
            </geometry>
        </collision>
        <inertial>
            <origin rpy="0 0 0" xyz="0.0127 -0.0171 -0.1414"/>
            <mass value="0.977826611"/>
            <inertia ixx="0.014928" ixy="8.8e-05" ixz="-0.001792" iyy="0.0158490785585" iyz="-0.000654" izz="0.001794"/>
        </inertial>
    </link>
    <!-- [rad] -->
    <!-- joint thigh KFE -->
    <joint name="RF_thigh_fixed_RF_KFE" type="fixed">
        <parent link="RF_thigh_fixed"/>
        <child link="RF_KFE"/>
        <origin rpy="0.261799387799 0 -1.57079632679" xyz="0.0 -0.086887 -0.282627"/>
    </joint>
    <!-- [m] -->
    <!-- [A] -->
    <!-- Drive link -->
    <link name="RF_KFE">
        <!--    <visual>-->
        <!--      <origin xyz="0 0 0" rpy="0 0 0"/>-->
        <!--      <geometry>-->
        <!--      <mesh filename="package://anymal_c_description/urdf/leg/drive/2_5_mesh.dae"-->
        <!--            scale="${anymal_meshes_scale}"/>-->
        <!--      </geometry>-->
        <!--    </visual>-->
        <!-- temporary visual, copied collision body -->
        <visual>
            <origin rpy="0 1.57079632679 0" xyz="-0.05 0 0"/>
            <geometry>
                <cylinder length="0.10" radius="0.05"/>
            </geometry>
        </visual>
        <collision>
            <origin rpy="0 1.57079632679 0" xyz="-0.05 0 0"/>
            <geometry>
                <cylinder length="0.10" radius="0.05"/>
            </geometry>
        </collision>
        <inertial>
            <origin rpy="0 0 0" xyz="-0.051008462309 4.2382171e-05 0.001928394422"/>
            <mass value="1.371293164"/>
            <inertia ixx="0.00132750404318" ixy="2.667453e-07" ixz="-6.5578582056e-05" iyy="0.00197358077377" iyz="1.305902533e-06" izz="0.00183646051615"/>
        </inertial>
    </link>
    <!-- joint Drive output -->
    <joint name="RF_KFE" type="revolute">
        <parent link="RF_KFE"/>
        <child link="RF_SHANK"/>
        <origin rpy="0 0 0" xyz="0 0 0"/>
        <axis xyz="-1 0 0"/>
        <dynamics damping="0.0" friction="0.0"/>
    </joint>
    <!-- Drive output link -->
    <link name="RF_SHANK">
        <inertial>
            <origin rpy="0 0 0" xyz="0 0 0"/>
            <mass value="0.001"/>
            <inertia ixx="0.000001" ixy="0.0" ixz="0.0" iyy="0.000001" iyz="0.0" izz="0.000001"/>
        </inertial>
    </link>
    <!-- [m] -->
    <!-- measured -->
    <!-- joint KFE shank -->
    <joint name="RF_shank_RF_shank_fixed" type="fixed">
        <parent link="RF_SHANK"/>
        <child link="RF_shank_fixed"/>
        <origin rpy="0 0.261799387799 1.57079632679" xyz="0 0 0"/>
    </joint>
    <!-- Shank link -->
    <link name="RF_shank_fixed">
        <!--      <visual>-->
        <!--        <origin xyz="0 0 0" rpy="0 0 ${(front-1)*0.5*pi}"/>-->
        <!--        <geometry>-->
        <!--          <mesh -->
        <!--            filename="package://anymal_c_description/urdf/leg/shank/3_0_mesh${mirrored}.dae"-->
        <!--            scale="${anymal_meshes_scale}"/>-->
        <!--        </geometry>-->
        <!--      </visual>-->
        <!-- temporary visual, copied collision body -->
        <visual>
            <origin rpy="1.57079632679 0 0" xyz="0 -0.02 0"/>
            <geometry>
                <cylinder length="0.04" radius="0.06"/>
            </geometry>
        </visual>
        <visual>
            <origin rpy="1.57079632679 0 0" xyz="0.057499 -0.02 0"/>
            <geometry>
                <box size="0.114998 0.0675 0.04"/>
            </geometry>
        </visual>
        <!-- Shank collision -->
        <collision>
            <origin rpy="1.57079632679 0 0" xyz="0 -0.02 0"/>
            <geometry>
                <cylinder length="0.04" radius="0.06"/>
            </geometry>
        </collision>
        <collision>
            <origin rpy="1.57079632679 0 0" xyz="0.057499 -0.02 0"/>
            <geometry>
                <box size="0.114998 0.0675 0.04"/>
            </geometry>
        </collision>
        <inertial>
            <origin rpy="0 0 0" xyz="0.032845496765 -0.020087452943 0.000819464952"/>
            <mass value="0.3203472"/>
            <inertia ixx="0.000315561389972" ixy="1.0430108417e-05" ixz="1.4120800915e-05" iyy="0.00107764668281" iyz="-3.60309972e-07" izz="0.000870072710319"/>
        </inertial>
    </link>
    <!-- [m] -->
    <!-- joint shank foot -->
    <joint name="RF_shank_fixed_RF_FOOT" type="fixed">
        <parent link="RF_shank_fixed"/>
        <child link="RF_FOOT"/>
        <origin rpy="0 0 0" xyz="0.08748 -0.006 -0.342504"/>
    </joint>
    <!-- Foot link -->
    <link name="RF_FOOT">
        <!--      <visual>-->
        <!--        <origin xyz="0 0 0" rpy="0 0 ${(front-1)*0.5*pi}"/>-->
        <!--        <geometry>-->
        <!--          <mesh-->
        <!--              filename="package://anymal_c_description/urdf/leg/foot/3_0_mesh.dae"-->
        <!--              scale="${anymal_meshes_scale}"/>-->
        <!--        </geometry>-->
        <!--      </visual>-->
        <!-- temporary visual, copied collision body -->
        <visual>
            <origin rpy="0 0 0" xyz="0 0 0.171252"/>
            <geometry>
                <cylinder length="0.22504" radius="0.0175"/>
            </geometry>
        </visual>
        <visual>
            <origin xyz="0 0 0.0225"/>
            <geometry>
                <sphere radius="0.03"/>
            </geometry>
        </visual>
        <!-- Adapter collision -->
        <collision>
            <origin rpy="0 0 0" xyz="0 0 0.171252"/>
            <geometry>
                <cylinder length="0.22504" radius="0.0175"/>
            </geometry>
        </collision>
        <!-- Foot collision -->
        <collision>
            <origin xyz="0 0 0.0225"/>
            <geometry>
                <sphere radius="0.03"/>
            </geometry>
        </collision>
        <inertial>
            <origin rpy="0 0 0" xyz="0.08640071854 -4.566e-08 0.158952618655"/>
            <mass value="0.205145377"/>
            <inertia ixx="0.00315582473384" ixy="-2.7197e-10" ixz="0.000388520744383" iyy="0.00316202017111" iyz="-8.6741e-11" izz="8.1052626806e-05"/>
        </inertial>
    </link>
    <!-- Gazebo customization -->
    <gazebo reference="RF_FOOT">
        <kp>1000000.0</kp>
        <kd>100.0</kd>
        <mu1>0.8</mu1>
        <mu2>0.8</mu2>
    </gazebo>
    <!-- [rad] -->
    <!-- joint base HAA -->
    <joint name="base_LH_HAA" type="fixed">
        <parent link="base"/>
        <child link="LH_HAA"/>
        <origin rpy="-0.174532925199 0 -3.14159265359" xyz="-0.3 0.104 0.0"/>
    </joint>
    <!-- [m] -->
    <!-- [A] -->
    <!-- Drive link -->
    <link name="LH_HAA">
        <!--    <visual>-->
        <!--      <origin xyz="0 0 0" rpy="0 0 0"/>-->
        <!--      <geometry>-->
        <!--      <mesh filename="package://anymal_c_description/urdf/leg/drive/2_5_mesh.dae"-->
        <!--            scale="${anymal_meshes_scale}"/>-->
        <!--      </geometry>-->
        <!--    </visual>-->
        <!-- temporary visual, copied collision body -->
        <visual>
            <origin rpy="0 1.57079632679 0" xyz="-0.07 0 0"/>
            <geometry>
                <cylinder length="0.14" radius="0.05"/>
            </geometry>
        </visual>
        <inertial>
            <origin rpy="0 0 0" xyz="-0.051008462309 4.2382171e-05 0.001928394422"/>
            <mass value="1.371293164"/>
            <inertia ixx="0.00132750404318" ixy="2.667453e-07" ixz="-6.5578582056e-05" iyy="0.00197358077377" iyz="1.305902533e-06" izz="0.00183646051615"/>
        </inertial>
    </link>
    <!-- joint Drive output -->
    <joint name="LH_HAA" type="revolute">
        <parent link="LH_HAA"/>
        <child link="LH_HIP"/>
        <origin rpy="0 0 0" xyz="0 0 0"/>
        <axis xyz="-1 0 0"/>
        <dynamics damping="0.0" friction="0.0"/>
    </joint>
    <!-- Drive output link -->
    <link name="LH_HIP">
        <inertial>
            <origin rpy="0 0 0" xyz="0 0 0"/>
            <mass value="0.001"/>
            <inertia ixx="0.000001" ixy="0.0" ixz="0.0" iyy="0.000001" iyz="0.0" izz="0.000001"/>
        </inertial>
    </link>
    <!-- [kg * m^2] -->
    <!-- joint HAA hip -->
    <joint name="LH_HIP_LH_hip_fixed" type="fixed">
        <parent link="LH_HIP"/>
        <child link="LH_hip_fixed"/>
        <origin rpy="-0.174532925199 0 -3.14159265359" xyz="0 0 0"/>
    </joint>
    <!-- Hip link -->
    <link name="LH_hip_fixed">
        <!--      <visual>-->
        <!--        <origin xyz="0 0 0" rpy="0 0 ${(front-1)*0.5*pi}"/>-->
        <!--        <geometry>-->
        <!--          <mesh-->
        <!--            filename="package://anymal_c_description/urdf/leg/hip/3_0_mesh${mirrored}.dae"-->
        <!--            scale="${anymal_meshes_scale}"/>-->
        <!--        </geometry>-->
        <!--      </visual>-->
        <inertial>
            <origin rpy="0 0 0" xyz="-0.090762388354 0.000733055279 -0.001556575559"/>
            <mass value="0.490061659"/>
            <inertia ixx="0.00072708117274" ixy="8.107655694e-06" ixz="-2.1517369242e-05" iyy="0.00187018767039" iyz="2.508888647e-05" izz="0.00167883666103"/>
        </inertial>
    </link>
    <!-- [rad] -->
    <!-- joint hip HFE -->
    <joint name="LH_hip_fixed_LH_HFE" type="fixed">
        <parent link="LH_hip_fixed"/>
        <child link="LH_HFE"/>
        <origin rpy="0 0 1.57079632679" xyz="-0.06 0.0701 0.0"/>
    </joint>
    <!-- [m] -->
    <!-- [A] -->
    <!-- Drive link -->
    <link name="LH_HFE">
        <!--    <visual>-->
        <!--      <origin xyz="0 0 0" rpy="0 0 0"/>-->
        <!--      <geometry>-->
        <!--      <mesh filename="package://anymal_c_description/urdf/leg/drive/2_5_mesh.dae"-->
        <!--            scale="${anymal_meshes_scale}"/>-->
        <!--      </geometry>-->
        <!--    </visual>-->
        <!-- temporary visual, copied collision body -->
        <visual>
            <origin rpy="0 1.57079632679 0" xyz="-0.05 0 0"/>
            <geometry>
                <cylinder length="0.10" radius="0.05"/>
            </geometry>
        </visual>
        <collision>
            <origin rpy="0 1.57079632679 0" xyz="-0.05 0 0"/>
            <geometry>
                <cylinder length="0.10" radius="0.05"/>
            </geometry>
        </collision>
        <inertial>
            <origin rpy="0 0 0" xyz="-0.051008462309 4.2382171e-05 0.001928394422"/>
            <mass value="1.371293164"/>
            <inertia ixx="0.00132750404318" ixy="2.667453e-07" ixz="-6.5578582056e-05" iyy="0.00197358077377" iyz="1.305902533e-06" izz="0.00183646051615"/>
        </inertial>
    </link>
    <!-- joint Drive output -->
    <joint name="LH_HFE" type="revolute">
        <parent link="LH_HFE"/>
        <child link="LH_THIGH"/>
        <origin rpy="0 0 0" xyz="0 0 0"/>
        <axis xyz="1 0 0"/>
        <dynamics damping="0.0" friction="0.0"/>
    </joint>
    <!-- Drive output link -->
    <link name="LH_THIGH">
        <inertial>
            <origin rpy="0 0 0" xyz="0 0 0"/>
            <mass value="0.001"/>
            <inertia ixx="0.000001" ixy="0.0" ixz="0.0" iyy="0.000001" iyz="0.0" izz="0.000001"/>
        </inertial>
    </link>
    <!-- [m] -->
    <!-- measured -->
    <!-- joint HFE thigh -->
    <joint name="LH_THIGH_LH_thigh_fixed" type="fixed">
        <parent link="LH_THIGH"/>
        <child link="LH_thigh_fixed"/>
        <origin rpy="0 0 -1.57079632679" xyz="0 0 0"/>
    </joint>
    <!-- Thigh link -->
    <link name="LH_thigh_fixed">
        <!--      <visual>-->
        <!--        <origin xyz="0 0 0" rpy="0 0 ${(front-1) * 0.5 * pi}"/>-->
        <!--        <geometry>-->
        <!--          <mesh -->
        <!--            filename="package://anymal_c_description/urdf/leg/thigh/3_0_mesh${mirrored}.dae"-->
        <!--            scale="${anymal_meshes_scale}"/>-->
        <!--        </geometry>-->
        <!--      </visual>-->
        <!-- temporary visual, copied collision body -->
        <visual>
            <origin rpy="1.57079632679 0 0" xyz="0 0.04 0"/>
            <geometry>
                <cylinder length="0.08" radius="0.065"/>
            </geometry>
        </visual>
        <visual>
            <origin rpy="0 0 0" xyz="0 0.03 -0.1413135"/>
            <geometry>
                <box size="0.075 0.06 0.282627"/>
            </geometry>
        </visual>
        <!-- Thigh collision -->
        <collision>
            <origin rpy="1.57079632679 0 0" xyz="0 0.04 0"/>
            <geometry>
                <cylinder length="0.08" radius="0.065"/>
            </geometry>
        </collision>
        <collision>
            <origin rpy="0 0 0" xyz="0 0.03 -0.1413135"/>
            <geometry>
                <box size="0.075 0.06 0.282627"/>
            </geometry>
        </collision>
        <inertial>
            <origin rpy="0 0 0" xyz="-0.0127 0.0171 -0.1414"/>
            <mass value="0.977826611"/>
            <inertia ixx="0.014928" ixy="8.8e-05" ixz="0.001792" iyy="0.0158490785585" iyz="0.000654" izz="0.001794"/>
        </inertial>
    </link>
    <!-- [rad] -->
    <!-- joint thigh KFE -->
    <joint name="LH_thigh_fixed_LH_KFE" type="fixed">
        <parent link="LH_thigh_fixed"/>
        <child link="LH_KFE"/>
        <origin rpy="0.261799387799 0 1.57079632679" xyz="-0.0 0.086887 -0.282627"/>
    </joint>
    <!-- [m] -->
    <!-- [A] -->
    <!-- Drive link -->
    <link name="LH_KFE">
        <!--    <visual>-->
        <!--      <origin xyz="0 0 0" rpy="0 0 0"/>-->
        <!--      <geometry>-->
        <!--      <mesh filename="package://anymal_c_description/urdf/leg/drive/2_5_mesh.dae"-->
        <!--            scale="${anymal_meshes_scale}"/>-->
        <!--      </geometry>-->
        <!--    </visual>-->
        <!-- temporary visual, copied collision body -->
        <visual>
            <origin rpy="0 1.57079632679 0" xyz="-0.05 0 0"/>
            <geometry>
                <cylinder length="0.10" radius="0.05"/>
            </geometry>
        </visual>
        <collision>
            <origin rpy="0 1.57079632679 0" xyz="-0.05 0 0"/>
            <geometry>
                <cylinder length="0.10" radius="0.05"/>
            </geometry>
        </collision>
        <inertial>
            <origin rpy="0 0 0" xyz="-0.051008462309 4.2382171e-05 0.001928394422"/>
            <mass value="1.371293164"/>
            <inertia ixx="0.00132750404318" ixy="2.667453e-07" ixz="-6.5578582056e-05" iyy="0.00197358077377" iyz="1.305902533e-06" izz="0.00183646051615"/>
        </inertial>
    </link>
    <!-- joint Drive output -->
    <joint name="LH_KFE" type="revolute">
        <parent link="LH_KFE"/>
        <child link="LH_SHANK"/>
        <origin rpy="0 0 0" xyz="0 0 0"/>
        <axis xyz="1 0 0"/>
        <dynamics damping="0.0" friction="0.0"/>
    </joint>
    <!-- Drive output link -->
    <link name="LH_SHANK">
        <inertial>
            <origin rpy="0 0 0" xyz="0 0 0"/>
            <mass value="0.001"/>
            <inertia ixx="0.000001" ixy="0.0" ixz="0.0" iyy="0.000001" iyz="0.0" izz="0.000001"/>
        </inertial>
    </link>
    <!-- [m] -->
    <!-- measured -->
    <!-- joint KFE shank -->
    <joint name="LH_shank_LH_shank_fixed" type="fixed">
        <parent link="LH_SHANK"/>
        <child link="LH_shank_fixed"/>
        <origin rpy="0 -0.261799387799 -1.57079632679" xyz="0 0 0"/>
    </joint>
    <!-- Shank link -->
    <link name="LH_shank_fixed">
        <!--      <visual>-->
        <!--        <origin xyz="0 0 0" rpy="0 0 ${(front-1)*0.5*pi}"/>-->
        <!--        <geometry>-->
        <!--          <mesh -->
        <!--            filename="package://anymal_c_description/urdf/leg/shank/3_0_mesh${mirrored}.dae"-->
        <!--            scale="${anymal_meshes_scale}"/>-->
        <!--        </geometry>-->
        <!--      </visual>-->
        <!-- temporary visual, copied collision body -->
        <visual>
            <origin rpy="1.57079632679 0 0" xyz="0 0.02 0"/>
            <geometry>
                <cylinder length="0.04" radius="0.06"/>
            </geometry>
        </visual>
        <visual>
            <origin rpy="1.57079632679 0 0" xyz="-0.057499 0.02 0"/>
            <geometry>
                <box size="0.114998 0.0675 0.04"/>
            </geometry>
        </visual>
        <!-- Shank collision -->
        <collision>
            <origin rpy="1.57079632679 0 0" xyz="0 0.02 0"/>
            <geometry>
                <cylinder length="0.04" radius="0.06"/>
            </geometry>
        </collision>
        <collision>
            <origin rpy="1.57079632679 0 0" xyz="-0.057499 0.02 0"/>
            <geometry>
                <box size="0.114998 0.0675 0.04"/>
            </geometry>
        </collision>
        <inertial>
            <origin rpy="0 0 0" xyz="-0.032845496765 0.020087452943 0.000819464952"/>
            <mass value="0.3203472"/>
            <inertia ixx="0.000315561389972" ixy="1.0430108417e-05" ixz="-1.4120800915e-05" iyy="0.00107764668281" iyz="3.60309972e-07" izz="0.000870072710319"/>
        </inertial>
    </link>
    <!-- [m] -->
    <!-- joint shank foot -->
    <joint name="LH_shank_fixed_LH_FOOT" type="fixed">
        <parent link="LH_shank_fixed"/>
        <child link="LH_FOOT"/>
        <origin rpy="0 0 0" xyz="-0.08748 0.006 -0.342504"/>
    </joint>
    <!-- Foot link -->
    <link name="LH_FOOT">
        <!--      <visual>-->
        <!--        <origin xyz="0 0 0" rpy="0 0 ${(front-1)*0.5*pi}"/>-->
        <!--        <geometry>-->
        <!--          <mesh-->
        <!--              filename="package://anymal_c_description/urdf/leg/foot/3_0_mesh.dae"-->
        <!--              scale="${anymal_meshes_scale}"/>-->
        <!--        </geometry>-->
        <!--      </visual>-->
        <!-- temporary visual, copied collision body -->
        <visual>
            <origin rpy="0 0 0" xyz="0 0 0.171252"/>
            <geometry>
                <cylinder length="0.22504" radius="0.0175"/>
            </geometry>
        </visual>
        <visual>
            <origin xyz="0 0 0.0225"/>
            <geometry>
                <sphere radius="0.03"/>
            </geometry>
        </visual>
        <!-- Adapter collision -->
        <collision>
            <origin rpy="0 0 0" xyz="0 0 0.171252"/>
            <geometry>
                <cylinder length="0.22504" radius="0.0175"/>
            </geometry>
        </collision>
        <!-- Foot collision -->
        <collision>
            <origin xyz="0 0 0.0225"/>
            <geometry>
                <sphere radius="0.03"/>
            </geometry>
        </collision>
        <inertial>
            <origin rpy="0 0 0" xyz="-0.08640071854 4.566e-08 0.158952618655"/>
            <mass value="0.205145377"/>
            <inertia ixx="0.00315582473384" ixy="-2.7197e-10" ixz="-0.000388520744383" iyy="0.00316202017111" iyz="8.6741e-11" izz="8.1052626806e-05"/>
        </inertial>
    </link>
    <!-- Gazebo customization -->
    <gazebo reference="LH_FOOT">
        <kp>1000000.0</kp>
        <kd>100.0</kd>
        <mu1>0.8</mu1>
        <mu2>0.8</mu2>
    </gazebo>
    <!-- [rad] -->
    <!-- joint base HAA -->
    <joint name="base_RH_HAA" type="fixed">
        <parent link="base"/>
        <child link="RH_HAA"/>
        <origin rpy="0.174532925199 0 -3.14159265359" xyz="-0.3 -0.104 0.0"/>
    </joint>
    <!-- [m] -->
    <!-- [A] -->
    <!-- Drive link -->
    <link name="RH_HAA">
        <!--    <visual>-->
        <!--      <origin xyz="0 0 0" rpy="0 0 0"/>-->
        <!--      <geometry>-->
        <!--      <mesh filename="package://anymal_c_description/urdf/leg/drive/2_5_mesh.dae"-->
        <!--            scale="${anymal_meshes_scale}"/>-->
        <!--      </geometry>-->
        <!--    </visual>-->
        <!-- temporary visual, copied collision body -->
        <visual>
            <origin rpy="0 1.57079632679 0" xyz="-0.07 0 0"/>
            <geometry>
                <cylinder length="0.14" radius="0.05"/>
            </geometry>
        </visual>
        <inertial>
            <origin rpy="0 0 0" xyz="-0.051008462309 4.2382171e-05 0.001928394422"/>
            <mass value="1.371293164"/>
            <inertia ixx="0.00132750404318" ixy="2.667453e-07" ixz="-6.5578582056e-05" iyy="0.00197358077377" iyz="1.305902533e-06" izz="0.00183646051615"/>
        </inertial>
    </link>
    <!-- joint Drive output -->
    <joint name="RH_HAA" type="revolute">
        <parent link="RH_HAA"/>
        <child link="RH_HIP"/>
        <origin rpy="0 0 0" xyz="0 0 0"/>
        <axis xyz="-1 0 0"/>
        <dynamics damping="0.0" friction="0.0"/>
    </joint>
    <!-- Drive output link -->
    <link name="RH_HIP">
        <inertial>
            <origin rpy="0 0 0" xyz="0 0 0"/>
            <mass value="0.001"/>
            <inertia ixx="0.000001" ixy="0.0" ixz="0.0" iyy="0.000001" iyz="0.0" izz="0.000001"/>
        </inertial>
    </link>
    <!-- [kg * m^2] -->
    <!-- joint HAA hip -->
    <joint name="RH_HIP_RH_hip_fixed" type="fixed">
        <parent link="RH_HIP"/>
        <child link="RH_hip_fixed"/>
        <origin rpy="0.174532925199 0 -3.14159265359" xyz="0 0 0"/>
    </joint>
    <!-- Hip link -->
    <link name="RH_hip_fixed">
        <!--      <visual>-->
        <!--        <origin xyz="0 0 0" rpy="0 0 ${(front-1)*0.5*pi}"/>-->
        <!--        <geometry>-->
        <!--          <mesh-->
        <!--            filename="package://anymal_c_description/urdf/leg/hip/3_0_mesh${mirrored}.dae"-->
        <!--            scale="${anymal_meshes_scale}"/>-->
        <!--        </geometry>-->
        <!--      </visual>-->
        <inertial>
            <origin rpy="0 0 0" xyz="-0.090762388354 -0.000733055279 -0.001556575559"/>
            <mass value="0.490061659"/>
            <inertia ixx="0.00072708117274" ixy="-8.107655694e-06" ixz="-2.1517369242e-05" iyy="0.00187018767039" iyz="-2.508888647e-05" izz="0.00167883666103"/>
        </inertial>
    </link>
    <!-- [rad] -->
    <!-- joint hip HFE -->
    <joint name="RH_hip_fixed_RH_HFE" type="fixed">
        <parent link="RH_hip_fixed"/>
        <child link="RH_HFE"/>
        <origin rpy="0 0 -1.57079632679" xyz="-0.06 -0.0701 0.0"/>
    </joint>
    <!-- [m] -->
    <!-- [A] -->
    <!-- Drive link -->
    <link name="RH_HFE">
        <!--    <visual>-->
        <!--      <origin xyz="0 0 0" rpy="0 0 0"/>-->
        <!--      <geometry>-->
        <!--      <mesh filename="package://anymal_c_description/urdf/leg/drive/2_5_mesh.dae"-->
        <!--            scale="${anymal_meshes_scale}"/>-->
        <!--      </geometry>-->
        <!--    </visual>-->
        <!-- temporary visual, copied collision body -->
        <visual>
            <origin rpy="0 1.57079632679 0" xyz="-0.05 0 0"/>
            <geometry>
                <cylinder length="0.10" radius="0.05"/>
            </geometry>
        </visual>
        <collision>
            <origin rpy="0 1.57079632679 0" xyz="-0.05 0 0"/>
            <geometry>
                <cylinder length="0.10" radius="0.05"/>
            </geometry>
        </collision>
        <inertial>
            <origin rpy="0 0 0" xyz="-0.051008462309 4.2382171e-05 0.001928394422"/>
            <mass value="1.371293164"/>
            <inertia ixx="0.00132750404318" ixy="2.667453e-07" ixz="-6.5578582056e-05" iyy="0.00197358077377" iyz="1.305902533e-06" izz="0.00183646051615"/>
        </inertial>
    </link>
    <!-- joint Drive output -->
    <joint name="RH_HFE" type="revolute">
        <parent link="RH_HFE"/>
        <child link="RH_THIGH"/>
        <origin rpy="0 0 0" xyz="0 0 0"/>
        <axis xyz="-1 0 0"/>
        <dynamics damping="0.0" friction="0.0"/>
    </joint>
    <!-- Drive output link -->
    <link name="RH_THIGH">
        <inertial>
            <origin rpy="0 0 0" xyz="0 0 0"/>
            <mass value="0.001"/>
            <inertia ixx="0.000001" ixy="0.0" ixz="0.0" iyy="0.000001" iyz="0.0" izz="0.000001"/>
        </inertial>
    </link>
    <!-- [m] -->
    <!-- measured -->
    <!-- joint HFE thigh -->
    <joint name="RH_THIGH_RH_thigh_fixed" type="fixed">
        <parent link="RH_THIGH"/>
        <child link="RH_thigh_fixed"/>
        <origin rpy="0 0 1.57079632679" xyz="0 0 0"/>
    </joint>
    <!-- Thigh link -->
    <link name="RH_thigh_fixed">
        <!--      <visual>-->
        <!--        <origin xyz="0 0 0" rpy="0 0 ${(front-1) * 0.5 * pi}"/>-->
        <!--        <geometry>-->
        <!--          <mesh -->
        <!--            filename="package://anymal_c_description/urdf/leg/thigh/3_0_mesh${mirrored}.dae"-->
        <!--            scale="${anymal_meshes_scale}"/>-->
        <!--        </geometry>-->
        <!--      </visual>-->
        <!-- temporary visual, copied collision body -->
        <visual>
            <origin rpy="1.57079632679 0 0" xyz="0 -0.04 0"/>
            <geometry>
                <cylinder length="0.08" radius="0.065"/>
            </geometry>
        </visual>
        <visual>
            <origin rpy="0 0 0" xyz="0 -0.03 -0.1413135"/>
            <geometry>
                <box size="0.075 0.06 0.282627"/>
            </geometry>
        </visual>
        <!-- Thigh collision -->
        <collision>
            <origin rpy="1.57079632679 0 0" xyz="0 -0.04 0"/>
            <geometry>
                <cylinder length="0.08" radius="0.065"/>
            </geometry>
        </collision>
        <collision>
            <origin rpy="0 0 0" xyz="0 -0.03 -0.1413135"/>
            <geometry>
                <box size="0.075 0.06 0.282627"/>
            </geometry>
        </collision>
        <inertial>
            <origin rpy="0 0 0" xyz="-0.0127 -0.0171 -0.1414"/>
            <mass value="0.977826611"/>
            <inertia ixx="0.014928" ixy="-8.8e-05" ixz="0.001792" iyy="0.0158490785585" iyz="-0.000654" izz="0.001794"/>
        </inertial>
    </link>
    <!-- [rad] -->
    <!-- joint thigh KFE -->
    <joint name="RH_thigh_fixed_RH_KFE" type="fixed">
        <parent link="RH_thigh_fixed"/>
        <child link="RH_KFE"/>
        <origin rpy="-0.261799387799 0 -1.57079632679" xyz="-0.0 -0.086887 -0.282627"/>
    </joint>
    <!-- [m] -->
    <!-- [A] -->
    <!-- Drive link -->
    <link name="RH_KFE">
        <!--    <visual>-->
        <!--      <origin xyz="0 0 0" rpy="0 0 0"/>-->
        <!--      <geometry>-->
        <!--      <mesh filename="package://anymal_c_description/urdf/leg/drive/2_5_mesh.dae"-->
        <!--            scale="${anymal_meshes_scale}"/>-->
        <!--      </geometry>-->
        <!--    </visual>-->
        <!-- temporary visual, copied collision body -->
        <visual>
            <origin rpy="0 1.57079632679 0" xyz="-0.05 0 0"/>
            <geometry>
                <cylinder length="0.10" radius="0.05"/>
            </geometry>
        </visual>
        <collision>
            <origin rpy="0 1.57079632679 0" xyz="-0.05 0 0"/>
            <geometry>
                <cylinder length="0.10" radius="0.05"/>
            </geometry>
        </collision>
        <inertial>
            <origin rpy="0 0 0" xyz="-0.051008462309 4.2382171e-05 0.001928394422"/>
            <mass value="1.371293164"/>
            <inertia ixx="0.00132750404318" ixy="2.667453e-07" ixz="-6.5578582056e-05" iyy="0.00197358077377" iyz="1.305902533e-06" izz="0.00183646051615"/>
        </inertial>
    </link>
    <!-- joint Drive output -->
    <joint name="RH_KFE" type="revolute">
        <parent link="RH_KFE"/>
        <child link="RH_SHANK"/>
        <origin rpy="0 0 0" xyz="0 0 0"/>
        <axis xyz="-1 0 0"/>
        <dynamics damping="0.0" friction="0.0"/>
    </joint>
    <!-- Drive output link -->
    <link name="RH_SHANK">
        <inertial>
            <origin rpy="0 0 0" xyz="0 0 0"/>
            <mass value="0.001"/>
            <inertia ixx="0.000001" ixy="0.0" ixz="0.0" iyy="0.000001" iyz="0.0" izz="0.000001"/>
        </inertial>
    </link>
    <!-- [m] -->
    <!-- measured -->
    <!-- joint KFE shank -->
    <joint name="RH_shank_RH_shank_fixed" type="fixed">
        <parent link="RH_SHANK"/>
        <child link="RH_shank_fixed"/>
        <origin rpy="0 -0.261799387799 1.57079632679" xyz="0 0 0"/>
    </joint>
    <!-- Shank link -->
    <link name="RH_shank_fixed">
        <!--      <visual>-->
        <!--        <origin xyz="0 0 0" rpy="0 0 ${(front-1)*0.5*pi}"/>-->
        <!--        <geometry>-->
        <!--          <mesh -->
        <!--            filename="package://anymal_c_description/urdf/leg/shank/3_0_mesh${mirrored}.dae"-->
        <!--            scale="${anymal_meshes_scale}"/>-->
        <!--        </geometry>-->
        <!--      </visual>-->
        <!-- temporary visual, copied collision body -->
        <visual>
            <origin rpy="1.57079632679 0 0" xyz="0 -0.02 0"/>
            <geometry>
                <cylinder length="0.04" radius="0.06"/>
            </geometry>
        </visual>
        <visual>
            <origin rpy="1.57079632679 0 0" xyz="-0.057499 -0.02 0"/>
            <geometry>
                <box size="0.114998 0.0675 0.04"/>
            </geometry>
        </visual>
        <!-- Shank collision -->
        <collision>
            <origin rpy="1.57079632679 0 0" xyz="0 -0.02 0"/>
            <geometry>
                <cylinder length="0.04" radius="0.06"/>
            </geometry>
        </collision>
        <collision>
            <origin rpy="1.57079632679 0 0" xyz="-0.057499 -0.02 0"/>
            <geometry>
                <box size="0.114998 0.0675 0.04"/>
            </geometry>
        </collision>
        <inertial>
            <origin rpy="0 0 0" xyz="-0.032845496765 -0.020087452943 0.000819464952"/>
            <mass value="0.3203472"/>
            <inertia ixx="0.000315561389972" ixy="-1.0430108417e-05" ixz="-1.4120800915e-05" iyy="0.00107764668281" iyz="-3.60309972e-07" izz="0.000870072710319"/>
        </inertial>
    </link>
    <!-- [m] -->
    <!-- joint shank foot -->
    <joint name="RH_shank_fixed_RH_FOOT" type="fixed">
        <parent link="RH_shank_fixed"/>
        <child link="RH_FOOT"/>
        <origin rpy="0 0 0" xyz="-0.08748 -0.006 -0.342504"/>
    </joint>
    <!-- Foot link -->
    <link name="RH_FOOT">
        <!--      <visual>-->
        <!--        <origin xyz="0 0 0" rpy="0 0 ${(front-1)*0.5*pi}"/>-->
        <!--        <geometry>-->
        <!--          <mesh-->
        <!--              filename="package://anymal_c_description/urdf/leg/foot/3_0_mesh.dae"-->
        <!--              scale="${anymal_meshes_scale}"/>-->
        <!--        </geometry>-->
        <!--      </visual>-->
        <!-- temporary visual, copied collision body -->
        <visual>
            <origin rpy="0 0 0" xyz="0 0 0.171252"/>
            <geometry>
                <cylinder length="0.22504" radius="0.0175"/>
            </geometry>
        </visual>
        <visual>
            <origin xyz="0 0 0.0225"/>
            <geometry>
                <sphere radius="0.03"/>
            </geometry>
        </visual>
        <!-- Adapter collision -->
        <collision>
            <origin rpy="0 0 0" xyz="0 0 0.171252"/>
            <geometry>
                <cylinder length="0.22504" radius="0.0175"/>
            </geometry>
        </collision>
        <!-- Foot collision -->
        <collision>
            <origin xyz="0 0 0.0225"/>
            <geometry>
                <sphere radius="0.03"/>
            </geometry>
        </collision>
        <inertial>
            <origin rpy="0 0 0" xyz="-0.08640071854 -4.566e-08 0.158952618655"/>
            <mass value="0.205145377"/>
            <inertia ixx="0.00315582473384" ixy="2.7197e-10" ixz="-0.000388520744383" iyy="0.00316202017111" iyz="-8.6741e-11" izz="8.1052626806e-05"/>
        </inertial>
    </link>
    <!-- Gazebo customization -->
    <gazebo reference="RH_FOOT">
        <kp>1000000.0</kp>
        <kd>100.0</kd>
        <mu1>0.8</mu1>
        <mu2>0.8</mu2>
    </gazebo>
</robot>
