<?xml version="1.0"?>
<robot name="Cartpole">
    <link name="world">  </link>


    <joint name="world_to_gantry" type="fixed">
        <axis xyz="0 0 0"/>
        <origin xyz="0.0 0.0 7" rpy="0 1.57 0"/>
        <parent link="world"/>
        <child link="gantry"/>
    </joint>
    <link name="gantry">
        <visual>
            <geometry>
                <cylinder radius="0.1" length="40"/>
            </geometry>
            <origin xyz="0 0 0" rpy="0 0 0"/>
        </visual>
    </link>

    <link name="cantileven">
        <visual>
            <geometry>
                <cylinder radius="0.1" length="0.4"/>
            </geometry>
            <origin xyz="0 0 0" rpy="0 0 0"/>
        </visual>
    </link>

    <joint name="slider" type="prismatic">
        <axis xyz="0 1 0"/>
        <origin xyz="0 0 0" rpy="1.57 0 0"/>
        <parent link="gantry"/>
        <child link="cantileven"/>
        <limit lower="-15" upper="15" velocity="3" effort="100"/>
    </joint>

    <link name="slider_up">
        <visual>
            <geometry>
                <cylinder radius="0.03" length="6"/>
            </geometry>
            <origin xyz="0 0 3"/>
        </visual>
    </link>

    <joint name="fix1" type="fixed">
        <parent link="cantileven"/>
        <child link="slider_up"/>
        <origin xyz="0 0 0" rpy="0 1.57 0"/>
    </joint>


    <joint name="rope_p" type="prismatic">
        <axis xyz="0 0 1"/>
        <parent link="slider_up"/>
        <child link="slider_down"/>
        <origin xyz="0 0 5.25" rpy="0 0 0"/>
        <limit lower="-4" upper="1.3" />
    </joint>

    <link name="slider_down">
        <visual>
            <geometry>
                <cylinder radius="0.03" length="1"/>
            </geometry>
            <origin xyz="0 0 0" rpy="0 0 0"/>
        </visual>
    </link>
    <joint name="fix2" type="fixed">
        <!--        <axis xyz="0 0 1"/>-->
        <parent link="slider_down"/>
        <child link="body"/>
        <origin xyz="0 0 0.5" rpy="-1.57 0 0"/>
    </joint>

    <link name="body">
        <inertial>
            <mass value="2"/>
            <inertia ixx="2.0" ixy="0.0" ixz="0.0" iyy="1.0" iyz="0.0" izz="2.0"/>
        </inertial>
        <collision>
            <geometry>
                <cylinder radius="0.1" length="0.2"/>
            </geometry>
            <origin xyz="0 0 0" rpy="0 1.57 0"/>
        </collision>
        <visual>
            <geometry>
                <cylinder radius="0.1" length="0.2"/>
            </geometry>
            <origin xyz="0 0 0" rpy="0 1.57 0"/>
        </visual>
    </link>

    <link name="thigh">
        <visual>
            <origin xyz="0 0 0.3" rpy="0 0 0"/>
            <geometry>
                <cylinder radius="0.05" length="0.6"/>
            </geometry>
        </visual>
        <collision>
            <origin xyz="0 0 0.3" rpy="0 0 0"/>
            <geometry>
                <cylinder radius="0.05" length="0.6"/>
            </geometry>
        </collision>
        <inertial>
            <mass value="5"/>
            <inertia ixx="1.0" ixy="0.0" ixz="0.0" iyy="1.0" iyz="0.0" izz="1.0"/>
        </inertial>
    </link>
    <link name="knee">
        <visual>
            <origin xyz="0 0 0" rpy="0 0 0"/>
            <geometry>
                <cylinder radius="0.05" length="0.10"/>
            </geometry>
        </visual>
        <collision>
            <origin xyz="0 0 0" rpy="0 0 0"/>
            <geometry>
                <cylinder radius="0.05" length="0.10"/>
            </geometry>
        </collision>
        <inertial>
            <mass value="1"/>
            <inertia ixx="1.0" ixy="0.0" ixz="0.0" iyy="1.0" iyz="0.0" izz="1.0"/>
        </inertial>
    </link>


    <link name="shank">
        <visual>
            <origin xyz="0 0 0.3" rpy="0 0 0"/>
            <geometry>
                <cylinder radius="0.05" length="0.6"/>
            </geometry>
        </visual>
        <collision>
            <origin xyz="0 0 0.3" rpy="0 0 0"/>
            <geometry>
                <cylinder radius="0.05" length="0.6"/>
            </geometry>
        </collision>
        <inertial>
            <mass value="4"/>
            <inertia ixx="1.0" ixy="0.0" ixz="0.0" iyy="1.0" iyz="0.0" izz="1.0"/>
        </inertial>
    </link>

    <link name="ankle">
        <visual>
            <origin xyz="0 0 0" rpy="0 0 0"/>
            <geometry>
                <cylinder radius="0.05" length="0.10"/>
            </geometry>
        </visual>
        <collision>
            <origin xyz="0 0 0" rpy="0 0 0"/>
            <geometry>
                <cylinder radius="0.05" length="0.10"/>
            </geometry>
        </collision>
        <inertial>
            <mass value="1"/>
            <inertia ixx="1.0" ixy="0.0" ixz="0.0" iyy="1.0" iyz="0.0" izz="1.0"/>
        </inertial>
    </link>

    <link name="sole">
        <visual>
            <origin xyz="0 0 0.15" rpy="0 0 0"/>
            <geometry>
                <cylinder radius="0.05" length="0.3"/>
            </geometry>
        </visual>
        <collision>
            <origin xyz="0 0 0.15" rpy="0 0 0"/>
            <geometry>
                <cylinder radius="0.05" length="0.3"/>
            </geometry>
        </collision>
        <inertial>
            <mass value="3"/>
            <inertia ixx="1.0" ixy="0.0" ixz="0.0" iyy="1.0" iyz="0.0" izz="1.0"/>
        </inertial>
    </link>
    >

    <joint name="hip_r" type="revolute">
        <axis xyz="0 1 0"/>
        <parent link="body"/>
        <child link="thigh"/>
        <origin xyz="0.0 0 0" rpy="1.57 1.57 0"/>
        <limit lower="-2" upper="1" effort="100" velocity="30"/>
    </joint>

    <joint name="knee_r" type="revolute">
        <axis xyz="0 0 1"/>
        <parent link="thigh"/>
        <child link="knee"/>
        <origin xyz="0 0 0.6" rpy="1.57 0 0 "/>
        <limit lower="-3" upper="0.2" effort="100" velocity="30"/>
    </joint>

    <joint name="fix3" type="fixed">
        <axis xyz="0 1 0"/>
        <parent link="knee"/>
        <child link="shank"/>
        <origin xyz="0.0 0.0 0.0" rpy="-1.57 0 0 "/>
    </joint>
    <joint name="ankle_r" type="revolute">
        <axis xyz="0 0 1"/>
        <parent link="shank"/>
        <child link="ankle"/>
        <origin xyz="0 0 0.6" rpy="1.57 1.57 0 "/>
        <limit lower="-1.3" upper="1.3" effort="100" velocity="100"/>
    </joint>
    <joint name="fix4" type="fixed">
        <axis xyz="0 0 1"/>
        <parent link="ankle"/>
        <child link="sole"/>
        <origin xyz="0 0 0" rpy="1.57 0 0 "/>
    </joint>

</robot>