<?xml version="1.0" ?>
<!-- =================================================================================== -->
<!-- |    This document was autogenerated by xacro from /home/koen/catkin_ws/src/smb_common/smb_description/urdf/smb_standalone.urdf.xacro | -->
<!-- |    EDITING THIS FILE BY HAND IS NOT RECOMMENDED                                 | -->
<!-- =================================================================================== -->
<robot name="smb"
  xmlns:xacro="http://www.ros.org/wiki/xacro">
  <!-- Materials -->
  <material name="black">
    <color rgba="0 0 0 255"/>
  </material>
  <material name="blue">
    <color rgba="0 0 200 255"/>
  </material>
  <material name="green">
    <color rgba="0 200 0 255"/>
  </material>
  <material name="grey">
    <color rgba="50 50 50 255"/>
  </material>
  <material name="orange">
    <color rgba="255 108 10 255"/>
  </material>
  <material name="brown">
    <color rgba="222 207 195 255"/>
  </material>
  <material name="red">
    <color rgba="200 0 0 255"/>
  </material>
  <material name="white">
    <color rgba="255 255 255 255"/>
  </material>
  <!-- continuous for gazebo -->
  <!-- Global Properties -->
  <!--xacro:property name="robot_name" value="smb"/-->
  <link name="base">
    <collision>
      <origin rpy="0 0 0" xyz="0 0 0"/>
      <geometry>
        <box size="0.6 0.41 0.22"/>
      </geometry>
    </collision>
    <visual>
      <origin rpy="0 0 0" xyz="0 0 0"/>
      <geometry>
        <box size="0.6 0.41 0.22"/>
      </geometry>
      <material name="green"/>
    </visual>
  </link>

  <!-- Fixed joint to add dummy inertia link -->
  <joint name="base_to_base_inertia" type="fixed">
    <parent link="base"/>
    <child link="base_inertia"/>
    <origin rpy="0 0 0" xyz="0 0 0"/>
  </joint>
  <!-- Dummy inertia link, because KDL cannot have inertia on the base link -->
  <link name="base_inertia">
    <inertial>
      <origin rpy="0 0 0" xyz="0.0 -0.02 0.047"/>
      <mass value="74.62"/>
      <inertia ixx="0.721666666667" ixy="0" ixz="0" iyy="1.36133333333" iyz="0" izz="1.36133333333"/>
    </inertial>
  </link>

  <joint name="LF_WHEEL" type="continuous">
    <parent link="base"/>
    <child link="LF_WHEEL"/>
    <origin rpy="1.57079632679 0 0" xyz="0.2159 0.255 0.0"/>
    <axis rpy="0 0 0" xyz="0 0 1"/>
    <dynamics damping="0.0" friction="0.0"/>
    <limit effort="65" velocity="25"/>
    <joint_properties damping="0.2" friction="0.2"/>
  </joint>
  <link name="LF_WHEEL">
    <collision>
      <origin rpy="0 0 0" xyz="0 0 0"/>
      <geometry>
        <cylinder length="0.08" radius="0.1975"/>
      </geometry>
    </collision>
    <visual>
      <origin rpy="0 0 0" xyz="0 0 0"/>
      <geometry>
        <cylinder length="0.08" radius="0.1975"/>
      </geometry>
      <material name="black"/>
    </visual>
    <inertial>
      <origin rpy="0 0 0" xyz="0 0 0"/>
      <mass value="5.73"/>
      <inertia ixx="0.059" ixy="0" ixz="0" iyy="0.059" iyz="0" izz="0.112"/>
    </inertial>
  </link>

  <joint name="RF_WHEEL" type="continuous">
    <parent link="base"/>
    <child link="RF_WHEEL"/>
    <origin rpy="1.57079632679 0 0" xyz="0.2159 -0.255 0.0"/>
    <axis rpy="0 0 0" xyz="0 0 1"/>
    <dynamics damping="0.0" friction="0.0"/>
    <limit effort="65" velocity="25"/>
    <joint_properties damping="0.2" friction="0.2"/>
  </joint>
  <link name="RF_WHEEL">
    <collision>
      <origin rpy="0 0 0" xyz="0 0 0"/>
      <geometry>
        <cylinder length="0.08" radius="0.1975"/>
      </geometry>
    </collision>
    <visual>
      <origin rpy="0 0 0" xyz="0 0 0"/>
      <geometry>
        <cylinder length="0.08" radius="0.1975"/>
      </geometry>
      <material name="black"/>
    </visual>
    <inertial>
      <origin rpy="0 0 0" xyz="0 0 0"/>
      <mass value="5.73"/>
      <inertia ixx="0.059" ixy="0" ixz="0" iyy="0.059" iyz="0" izz="0.112"/>
    </inertial>
  </link>

  <joint name="LH_WHEEL" type="continuous">
    <parent link="base"/>
    <child link="LH_WHEEL"/>
    <origin rpy="1.57079632679 0 0" xyz="-0.2159 0.255 0.0"/>
    <axis rpy="0 0 0" xyz="0 0 1"/>
    <dynamics damping="0.0" friction="0.0"/>
    <limit effort="65" velocity="25"/>
    <joint_properties damping="0.2" friction="0.2"/>
  </joint>
  <link name="LH_WHEEL">
    <collision>
      <origin rpy="0 0 0" xyz="0 0 0"/>
      <geometry>
        <cylinder length="0.08" radius="0.1975"/>
      </geometry>
    </collision>
    <visual>
      <origin rpy="0 0 0" xyz="0 0 0"/>
      <geometry>
        <cylinder length="0.08" radius="0.1975"/>
      </geometry>
      <material name="black"/>
    </visual>
    <inertial>
      <origin rpy="0 0 0" xyz="0 0 0"/>
      <mass value="5.73"/>
      <inertia ixx="0.059" ixy="0" ixz="0" iyy="0.059" iyz="0" izz="0.112"/>
    </inertial>
  </link>

  <joint name="RH_WHEEL" type="continuous">
    <parent link="base"/>
    <child link="RH_WHEEL"/>
    <origin rpy="1.57079632679 0 0" xyz="-0.2159 -0.255 0.0"/>
    <axis rpy="0 0 0" xyz="0 0 1"/>
    <dynamics damping="0.0" friction="0.0"/>
    <limit effort="65" velocity="25"/>
    <joint_properties damping="0.2" friction="0.2"/>
  </joint>
  <link name="RH_WHEEL">
    <collision>
      <origin rpy="0 0 0" xyz="0 0 0"/>
      <geometry>
        <cylinder length="0.08" radius="0.1975"/>
      </geometry>
    </collision>
    <visual>
      <origin rpy="0 0 0" xyz="0 0 0"/>
      <geometry>
        <cylinder length="0.08" radius="0.1975"/>
      </geometry>
      <material name="black"/>
    </visual>
    <inertial>
      <origin rpy="0 0 0" xyz="0 0 0"/>
      <mass value="5.73"/>
      <inertia ixx="0.059" ixy="0" ixz="0" iyy="0.059" iyz="0" izz="0.112"/>
    </inertial>
  </link>

  <link name="imu">
    <visual>
      <origin rpy="0 0 0" xyz="0 0 0"/>
      <geometry>
        <box size="0.08 0.055 0.024"/>
      </geometry>
      <material name="black"/>
    </visual>
  </link>
  <joint name="imu" type="fixed">
    <parent link="base"/>
    <child link="imu"/>
    <origin rpy="3.14159 1.57079632679 0" xyz="0.312 0 -0.07"/>
  </joint>

  <link name="lidar">
    <visual>
      <origin rpy="0 0 0" xyz="0 0 0"/>
      <geometry>
        <cylinder radius="0.05" length="0.2"/>
      </geometry>
      <material name="black"/>
    </visual>
  </link>
  <joint name="lidar" type="fixed">
    <parent link="base"/>
    <child link="lidar"/>
    <origin rpy="0 0 0" xyz="0 0 0.2"/>
  </joint>

</robot>
