<?xml version="1.0" ?>
<!-- =================================================================================== -->
<!-- |    This document was autogenerated by xacro from ../urdf/husky.urdf.xacro       | -->
<!-- |    EDITING THIS FILE BY HAND IS NOT RECOMMENDED                                 | -->
<!-- =================================================================================== -->
<!--
Software License Agreement (BSD)

\file      husky.urdf.xacro
\authors   Paul Bovbel <pbovbel@clearpathrobotics.com>
\copyright Copyright (c) 2015, Clearpath Robotics, Inc., All rights reserved.

Redistribution and use in source and binary forms, with or without modification, are permitted provided that
the following conditions are met:
 * Redistributions of source code must retain the above copyright notice, this list of conditions and the
   following disclaimer.
 * Redistributions in binary form must reproduce the above copyright notice, this list of conditions and the 
   following disclaimer in the documentation and/or other materials provided with the distribution.
 * Neither the name of Clearpath Robotics nor the names of its contributors may be used to endorse or promote
   products derived from this software without specific prior written permission.

THIS SOFTWARE IS PROVIDED BY THE COPYRIGHT HOLDERS AND CONTRIBUTORS "AS IS" AND ANY EXPRESS OR IMPLIED WAR-
RANTIES, INCLUDING, BUT NOT LIMITED TO, THE IMPLIED WARRANTIES OF MERCHANTABILITY AND FITNESS FOR A PARTICULAR
PURPOSE ARE DISCLAIMED. IN NO EVENT SHALL THE COPYRIGHT HOLDER OR CONTRIBUTORS BE LIABLE FOR ANY DIRECT, IN-
DIRECT, INCIDENTAL, SPECIAL, EXEMPLARY, OR CONSEQUENTIAL DAMAGES (INCLUDING, BUT NOT LIMITED TO, PROCUREMENT
OF SUBSTITUTE GOODS OR SERVICES; LOSS OF USE, DATA, OR PROFITS; OR BUSINESS INTERRUPTION) HOWEVER CAUSED AND
ON ANY THEORY OF LIABILITY, WHETHER IN CONTRACT, STRICT LIABILITY, OR TORT (INCLUDING NEGLIGENCE OR OTHERWISE)
ARISING IN ANY WAY OUT OF THE USE OF THIS SOFTWARE, EVEN IF ADVISED OF THE POSSIBILITY OF SUCH DAMAGE.
-->
<robot name="husky_robot" xmlns:xacro="http://ros.org/wiki/xacro">
  <!-- Included URDF/XACRO Files -->
  <material name="Black">
    <color rgba="0.1 0.1 0.1 1.0"/>
  </material>
  <material name="Blue">
    <color rgba="0.0 0.0 0.8 1.0"/>
  </material>
  <material name="Green">
    <color rgba="0.0 0.8 0.0 1.0"/>
  </material>
  <material name="Grey">
    <color rgba="0.7 0.7 0.7 1.0"/>
  </material>
  <material name="DarkGrey">
    <color rgba="0.3 0.3 0.3 1.0"/>
  </material>
  <material name="Red">
    <color rgba="0.8 0.0 0.0 1.0"/>
  </material>
  <material name="White">
    <color rgba="1.0 1.0 1.0 1.0"/>
  </material>
  <material name="Yellow">
    <color rgba="0.8 0.8 0.0 1.0"/>
  </material>
  <!-- Base Size -->
  <!-- Wheel Mounting Positions -->
  <!-- Wheel Properties -->
  <!-- Base link is on the ground under the robot -->

  <link name="base_link">
    <visual>
      <origin rpy="0 0 0" xyz="0 0 0.12498"/>
      <geometry>
        <!-- Make collision box slightly bigger in x and z directions. -->
        <box size="@@base_length @@base_width 0.2075"/>
      </geometry>
    </visual>
    <collision>
      <origin rpy="0 0 0" xyz="0 0 0.12498"/>
      <geometry>
        <!-- Make collision box slightly bigger in x and z directions. -->
        <box size="@@base_length @@base_width 0.2075"/>
      </geometry>
    </collision>
    <inertial>
      <mass value="{@@rho*@@base_length*@@base_width*0.2075}"/>
      <origin xyz="-0.08748 -0.00085 0.09947"/>
      <inertia ixx="0.6022" ixy="-0.02364" ixz="-0.1197" iyy="1.7386" iyz="-0.001544" izz="2.0296"/>
    </inertial>
  </link>

  <link name="front_left_wheel_link">
    <inertial>
      <mass value="{@@rho*@@wheel_width*@@wheel_radius*@@wheel_radius*3.1415}"/>
      <origin xyz="0 0 0"/>
      <inertia ixx="0.02467" ixy="0" ixz="0" iyy="0.02467" iyz="0" izz="0.04411"/>
    </inertial>
    <visual>
      <origin rpy="1.570795 0 0" xyz="0 0 0"/>
      <geometry>
        <cylinder length="@@wheel_width" radius="@@wheel_radius"/>
      </geometry>
    </visual>
    <collision>
      <origin rpy="1.570795 0 0" xyz="0 0 0"/>
      <geometry>
        <cylinder length="@@wheel_width" radius="@@wheel_radius"/>
      </geometry>
    </collision>
  </link>
  <joint name="front_left_wheel" type="continuous">
    <parent link="base_link"/>
    <child link="front_left_wheel_link"/>
    <origin rpy="0 0 0" xyz="{@@base_length*0.5} @@wheel_y_offset 0"/>
    <axis rpy="0 0 0" xyz="0 1 0"/>
  </joint>

  <link name="front_left_flipper_wheel_link">
    <inertial>
      <mass value="2.637"/>
      <origin xyz="0 0 0"/>
      <inertia ixx="0.02467" ixy="0" ixz="0" iyy="0.02467" iyz="0" izz="0.04411"/>
    </inertial>
  </link>
  <joint name="front_left_flipper_wheel" type="continuous">
    <parent link="base_link"/>
    <child link="front_left_flipper_wheel_link"/>
    <origin rpy="0 0 0" xyz="{@@base_length*0.5} @@track_y_offset 0"/>
    <axis rpy="0 0 0" xyz="0 1 0"/>
  </joint>

  <link name="front_left_flipper_wheel_link2">
    <inertial>
      <mass value="{@@rho*@@wheel_width*@@flipper_radius*@@flipper_radius*3.1415}"/>
      <origin xyz="0 0 0"/>
      <inertia ixx="0.02467" ixy="0" ixz="0" iyy="0.02467" iyz="0" izz="0.04411"/>
    </inertial>
    <visual>
      <origin rpy="1.570795 0 0" xyz="0 0 0"/>
      <geometry>
        <cylinder length="@@wheel_width" radius="@@flipper_radius"/>
      </geometry>
    </visual>
    <collision>
      <origin rpy="1.570795 0 0" xyz="0 0 0"/>
      <geometry>
        <cylinder length="@@wheel_width" radius="@@flipper_radius"/>
      </geometry>
    </collision>
  </link>
  <joint name="front_left_flipper_wheel2" type="continuous">
    <parent link="front_left_flipper_wheel_link"/>
    <child link="front_left_flipper_wheel_link2"/>
    <origin rpy="0 0 0" xyz="0 0 0"/>
    <axis rpy="0 0 0" xyz="0 1 0"/>
  </joint>


  <link name="front_left_flipper_wheel_link3">
    <inertial>
      <mass value="{@@rho*@@wheel_width*@@flipper_radius*@@flipper_radius*3.1415}"/>
      <origin xyz="0 0 0"/>
      <inertia ixx="0.02467" ixy="0" ixz="0" iyy="0.02467" iyz="0" izz="0.04411"/>
    </inertial>
    <visual>
      <origin rpy="1.570795 0 0" xyz="0 0 0"/>
      <geometry>
        <cylinder length="@@wheel_width" radius="@@flipper_radius"/>
      </geometry>
    </visual>
    <collision>
      <origin rpy="1.570795 0 0" xyz="0 0 0"/>
      <geometry>
        <cylinder length="@@wheel_width" radius="@@flipper_radius"/>
      </geometry>
    </collision>
  </link>
  <joint name="front_left_flipper_wheel3" type="continuous">
    <parent link="front_left_flipper_wheel_link"/>
    <child link="front_left_flipper_wheel_link3"/>
    <origin rpy="0 0 0" xyz="0.35 0 0"/>
    <axis rpy="0 0 0" xyz="0 1 0"/>
  </joint>


  <link name="front_right_wheel_link">
    <inertial>
      <mass value="{@@rho*@@wheel_width*@@wheel_radius*@@wheel_radius*3.1415}"/>
      <origin xyz="0 0 0"/>
      <inertia ixx="0.02467" ixy="0" ixz="0" iyy="0.02467" iyz="0" izz="0.04411"/>
    </inertial>
    <visual>
      <origin rpy="1.570795 0 0" xyz="0 0 0"/>
      <geometry>
        <cylinder length="@@wheel_width" radius="@@wheel_radius"/>
      </geometry>
    </visual>
    <collision>
      <origin rpy="1.570795 0 0" xyz="0 0 0"/>
      <geometry>
        <cylinder length="@@wheel_width" radius="@@wheel_radius"/>
      </geometry>
    </collision>
  </link>
  <joint name="front_right_wheel" type="continuous">
    <parent link="base_link"/>
    <child link="front_right_wheel_link"/>
    <origin rpy="0 0 0" xyz="{@@base_length*0.5} -@@wheel_y_offset 0"/>
    <axis rpy="0 0 0" xyz="0 1 0"/>
  </joint>

  <link name="front_right_flipper_wheel_link">
    <inertial>
      <mass value="{@@rho*@@wheel_width*@@flipper_radius*@@flipper_radius*3.1415}"/>
      <origin xyz="0 0 0"/>
      <inertia ixx="0.02467" ixy="0" ixz="0" iyy="0.02467" iyz="0" izz="0.04411"/>
    </inertial>
  </link>
  <joint name="front_right_flipper_wheel" type="continuous">
    <parent link="base_link"/>
    <child link="front_right_flipper_wheel_link"/>
    <origin rpy="0 0 0" xyz="{@@base_length*0.5} -@@track_y_offset 0"/>
    <axis rpy="0 0 0" xyz="0 1 0"/>
  </joint>


  <link name="front_right_flipper_wheel_link2">
    <inertial>
      <mass value="{@@rho*@@wheel_width*@@flipper_radius*@@flipper_radius*3.1415}"/>
      <origin xyz="0 0 0"/>
      <inertia ixx="0.02467" ixy="0" ixz="0" iyy="0.02467" iyz="0" izz="0.04411"/>
    </inertial>
    <visual>
      <origin rpy="1.570795 0 0" xyz="0 0 0"/>
      <geometry>
        <cylinder length="@@wheel_width" radius="@@flipper_radius"/>
      </geometry>
    </visual>
    <collision>
      <origin rpy="1.570795 0 0" xyz="0 0 0"/>
      <geometry>
        <cylinder length="@@wheel_width" radius="@@flipper_radius"/>
      </geometry>
    </collision>
  </link>

  <joint name="front_right_flipper_wheel2" type="continuous">
    <parent link="front_right_flipper_wheel_link"/>
    <child link="front_right_flipper_wheel_link2"/>
    <origin rpy="0 0 0" xyz="0 0 0"/>
    <axis rpy="0 0 0" xyz="0 1 0"/>
  </joint>

  <link name="front_right_flipper_wheel_link3">
    <inertial>
      <mass value="{@@rho*@@wheel_width*@@flipper_radius*@@flipper_radius*3.1415}"/>
      <origin xyz="0 0 0"/>
      <inertia ixx="0.02467" ixy="0" ixz="0" iyy="0.02467" iyz="0" izz="0.04411"/>
    </inertial>
    <visual>
      <origin rpy="1.570795 0 0" xyz="0 0 0"/>
      <geometry>
        <cylinder length="@@wheel_width" radius="@@flipper_radius"/>
      </geometry>
    </visual>
    <collision>
      <origin rpy="1.570795 0 0" xyz="0 0 0"/>
      <geometry>
        <cylinder length="@@wheel_width" radius="@@flipper_radius"/>
      </geometry>
    </collision>
  </link>

  <joint name="front_right_flipper_wheel3" type="continuous">
    <parent link="front_right_flipper_wheel_link"/>
    <child link="front_right_flipper_wheel_link3"/>
    <origin rpy="0 0 0" xyz="0.35 0 0"/>
    <axis rpy="0 0 0" xyz="0 1 0"/>
  </joint>

  <link name="rear_left_wheel_link">
    <inertial>
      <mass value="{@@rho*@@wheel_width*@@wheel_radius*@@wheel_radius*3.1415}"/>
      <origin xyz="0 0 0"/>
      <inertia ixx="0.02467" ixy="0" ixz="0" iyy="0.02467" iyz="0" izz="0.04411"/>
    </inertial>
    <visual>
      <origin rpy="1.570795 0 0" xyz="0 0 0"/>
      <geometry>
        <cylinder length="@@wheel_width" radius="@@wheel_radius"/>
      </geometry>
    </visual>
    <collision>
      <origin rpy="1.570795 0 0" xyz="0 0 0"/>
      <geometry>
        <cylinder length="@@wheel_width" radius="@@wheel_radius"/>
      </geometry>
    </collision>
  </link>
  <joint name="rear_left_wheel" type="continuous">
    <parent link="base_link"/>
    <child link="rear_left_wheel_link"/>
    <origin rpy="0 0 0" xyz="-{@@base_length*0.5} @@wheel_y_offset 0"/>
    <axis rpy="0 0 0" xyz="0 1 0"/>
  </joint>



  <link name="rear_right_wheel_link">
    <inertial>
      <mass value="{@@rho*@@wheel_width*@@wheel_radius*@@wheel_radius*3.1415}"/>
      <origin xyz="0 0 0"/>
      <inertia ixx="0.02467" ixy="0" ixz="0" iyy="0.02467" iyz="0" izz="0.04411"/>
    </inertial>
    <visual>
      <origin rpy="1.570795 0 0" xyz="0 0 0"/>
      <geometry>
        <cylinder length="@@wheel_width" radius="@@wheel_radius"/>
      </geometry>
    </visual>
    <collision>
      <origin rpy="1.570795 0 0" xyz="0 0 0"/>
      <geometry>
        <cylinder length="@@wheel_width" radius="@@wheel_radius"/>
      </geometry>
    </collision>
  </link>
  <joint name="rear_right_wheel" type="continuous">
    <parent link="base_link"/>
    <child link="rear_right_wheel_link"/>
    <origin rpy="0 0 0" xyz="-{@@base_length*0.5} -@@wheel_y_offset 0"/>
    <axis rpy="0 0 0" xyz="0 1 0"/>
  </joint>


  <link name="vertical_link">
    <inertial>
      <origin rpy="0 0 0" xyz="0.002284 -4.1e-05 0.025165"/>
      <mass value="0.5"/>
      <inertia ixx="0.073348887" ixy="0.00030338" ixz="0.001918218" iyy="0.250684593" iyz="-7.5402e-05" izz="0.254469458"/>
    </inertial>
  </link>
  <joint name="vertical_joint" type="prismatic">
    <origin rpy="0 0 0" xyz="0 @@wheel_y_offset -@@wheel_radius"/>
    <parent link="base_link"/>
    <child link="vertical_link"/>
    <axis xyz="0 0 1"/>
  </joint>
  <link name="horizontal_link">
    <visual>
      <origin rpy="0 0 0" xyz="0 0 0"/>
      <geometry>
        <box size="@@base_length @@wheel_width 0.005"/>
      </geometry>
    </visual>
    <collision>
      <origin rpy="0 0 0" xyz="0 0 0"/>
      <geometry>
        <box size="@@base_length @@wheel_width 0.005"/>
      </geometry>
    </collision>
    <inertial>
      <origin rpy="0 0 0" xyz="0.002284 -4.1e-05 0.025165"/>
      <mass value="0.5"/>
      <inertia ixx="0.073348887" ixy="0.00030338" ixz="0.001918218" iyy="0.250684593" iyz="-7.5402e-05" izz="0.254469458"/>
    </inertial>
  </link>
  <joint name="horizontal_joint" type="prismatic">
    <origin rpy="0 0 0" xyz="0 0 0"/>
    <parent link="vertical_link"/>
    <child link="horizontal_link"/>
    <axis xyz="1 0 0"/>
  </joint>


  <link name="vertical_link2">
    <inertial>
      <origin rpy="0 0 0" xyz="0.002284 -4.1e-05 0.025165"/>
      <mass value="0.5"/>
      <inertia ixx="0.073348887" ixy="0.00030338" ixz="0.001918218" iyy="0.250684593" iyz="-7.5402e-05" izz="0.254469458"/>
    </inertial>
  </link>
  <joint name="vertical_joint2" type="prismatic">
    <origin rpy="0 0 0" xyz="0 -@@wheel_y_offset -@@wheel_radius"/>
    <parent link="base_link"/>
    <child link="vertical_link2"/>
    <axis xyz="0 0 1"/>
  </joint>
  <link name="horizontal_link2">
    <visual>
      <origin rpy="0 0 0" xyz="0 0 0"/>
      <geometry>
        <box size="@@base_length @@wheel_width 0.005"/>
      </geometry>
    </visual>
    <collision>
      <origin rpy="0 0 0" xyz="0 0 0"/>
      <geometry>
        <box size="@@base_length @@wheel_width 0.005"/>
      </geometry>
    </collision>
    <inertial>
      <origin rpy="0 0 0" xyz="0.002284 -4.1e-05 0.025165"/>
      <mass value="0.5"/>
      <inertia ixx="0.073348887" ixy="0.00030338" ixz="0.001918218" iyy="0.250684593" iyz="-7.5402e-05" izz="0.254469458"/>
    </inertial>
  </link>
  <joint name="horizontal_joint2" type="prismatic">
    <origin rpy="0 0 0" xyz="0 0 0"/>
    <parent link="vertical_link2"/>
    <child link="horizontal_link2"/>
    <axis xyz="1 0 0"/>
  </joint>


  <link name="vertical_link3">
    <inertial>
      <origin rpy="0 0 0" xyz="0.002284 -4.1e-05 0.025165"/>
      <mass value="0.5"/>
      <inertia ixx="0.073348887" ixy="0.00030338" ixz="0.001918218" iyy="0.250684593" iyz="-7.5402e-05" izz="0.254469458"/>
    </inertial>
  </link>
  <joint name="vertical_joint3" type="prismatic">
    <origin rpy="0 0 0" xyz="0.19 0 -@@flipper_radius"/>
    <parent link="front_left_flipper_wheel_link"/>
    <child link="vertical_link3"/>
    <axis xyz="0 0 1"/>
  </joint>
  <link name="horizontal_link3">
    <visual>
      <origin rpy="0 0 0" xyz="0 0 0"/>
      <geometry>
        <box size="0.38 @@wheel_width 0.005"/>
      </geometry>
    </visual>
    <collision>
      <origin rpy="0 0 0" xyz="0 0 0"/>
      <geometry>
        <box size="0.38 @@wheel_width 0.005"/>
      </geometry>
    </collision>
    <inertial>
      <origin rpy="0 0 0" xyz="0.002284 -4.1e-05 0.025165"/>
      <mass value="0.5"/>
      <inertia ixx="0.073348887" ixy="0.00030338" ixz="0.001918218" iyy="0.250684593" iyz="-7.5402e-05" izz="0.254469458"/>
    </inertial>
  </link>
  <joint name="horizontal_joint3" type="prismatic">
    <origin rpy="0 0 0" xyz="0 0 0"/>
    <parent link="vertical_link3"/>
    <child link="horizontal_link3"/>
    <axis xyz="1 0 0"/>
  </joint>


  <link name="vertical_link4">
    <inertial>
      <origin rpy="0 0 0" xyz="0.002284 -4.1e-05 0.025165"/>
      <mass value="0.5"/>
      <inertia ixx="0.073348887" ixy="0.00030338" ixz="0.001918218" iyy="0.250684593" iyz="-7.5402e-05" izz="0.254469458"/>
    </inertial>
  </link>
  <joint name="vertical_joint4" type="prismatic">
    <origin rpy="0 0 0" xyz="0.19 0 -@@flipper_radius"/>
    <parent link="front_right_flipper_wheel_link"/>
    <child link="vertical_link4"/>
    <axis xyz="0 0 1"/>
  </joint>
  <link name="horizontal_link4">
    <visual>
      <origin rpy="0 0 0" xyz="0 0 0"/>
      <geometry>
        <box size="0.38 @@wheel_width 0.005"/>
      </geometry>
    </visual>
    <collision>
      <origin rpy="0 0 0" xyz="0 0 0"/>
      <geometry>
        <box size="0.38 @@wheel_width 0.005"/>
      </geometry>
    </collision>
    <inertial>
      <origin rpy="0 0 0" xyz="0.002284 -4.1e-05 0.025165"/>
      <mass value="0.5"/>
      <inertia ixx="0.073348887" ixy="0.00030338" ixz="0.001918218" iyy="0.250684593" iyz="-7.5402e-05" izz="0.254469458"/>
    </inertial>
  </link>
  <joint name="horizontal_joint4" type="prismatic">
    <origin rpy="0 0 0" xyz="0 0 0"/>
    <parent link="vertical_link4"/>
    <child link="horizontal_link4"/>
    <axis xyz="1 0 0"/>
  </joint>


  <link name="vertical_link5">
    <inertial>
      <origin rpy="0 0 0" xyz="0.002284 -4.1e-05 0.025165"/>
      <mass value="0.5"/>
      <inertia ixx="0.073348887" ixy="0.00030338" ixz="0.001918218" iyy="0.250684593" iyz="-7.5402e-05" izz="0.254469458"/>
    </inertial>
  </link>
  <joint name="vertical_joint5" type="prismatic">
    <origin rpy="0 0 0" xyz="0 @@wheel_y_offset @@wheel_radius"/>
    <parent link="base_link"/>
    <child link="vertical_link5"/>
    <axis xyz="0 0 1"/>
  </joint>
  <link name="horizontal_link5">
    <visual>
      <origin rpy="0 0 0" xyz="0 0 0"/>
      <geometry>
        <box size="@@base_length @@wheel_width 0.005"/>
      </geometry>
    </visual>
    <collision>
      <origin rpy="0 0 0" xyz="0 0 0"/>
      <geometry>
        <box size="@@base_length @@wheel_width 0.005"/>
      </geometry>
    </collision>
    <inertial>
      <origin rpy="0 0 0" xyz="0.002284 -4.1e-05 0.025165"/>
      <mass value="0.5"/>
      <inertia ixx="0.073348887" ixy="0.00030338" ixz="0.001918218" iyy="0.250684593" iyz="-7.5402e-05" izz="0.254469458"/>
    </inertial>
  </link>
  <joint name="horizontal_joint5" type="prismatic">
    <origin rpy="0 0 0" xyz="0 0 0"/>
    <parent link="vertical_link5"/>
    <child link="horizontal_link5"/>
    <axis xyz="1 0 0"/>
  </joint>


  <link name="vertical_link6">
    <inertial>
      <origin rpy="0 0 0" xyz="0.002284 -4.1e-05 0.025165"/>
      <mass value="0.5"/>
      <inertia ixx="0.073348887" ixy="0.00030338" ixz="0.001918218" iyy="0.250684593" iyz="-7.5402e-05" izz="0.254469458"/>
    </inertial>
  </link>
  <joint name="vertical_joint6" type="prismatic">
    <origin rpy="0 0 0" xyz="0 -@@wheel_y_offset @@wheel_radius"/>
    <parent link="base_link"/>
    <child link="vertical_link6"/>
    <axis xyz="0 0 1"/>
  </joint>
  <link name="horizontal_link6">
    <visual>
      <origin rpy="0 0 0" xyz="0 0 0"/>
      <geometry>
        <box size="@@base_length @@wheel_width 0.005"/>
      </geometry>
    </visual>
    <collision>
      <origin rpy="0 0 0" xyz="0 0 0"/>
      <geometry>
        <box size="@@base_length @@wheel_width 0.005"/>
      </geometry>
    </collision>
    <inertial>
      <origin rpy="0 0 0" xyz="0.002284 -4.1e-05 0.025165"/>
      <mass value="0.5"/>
      <inertia ixx="0.073348887" ixy="0.00030338" ixz="0.001918218" iyy="0.250684593" iyz="-7.5402e-05" izz="0.254469458"/>
    </inertial>
  </link>
  <joint name="horizontal_joint6" type="prismatic">
    <origin rpy="0 0 0" xyz="0 0 0"/>
    <parent link="vertical_link6"/>
    <child link="horizontal_link6"/>
    <axis xyz="1 0 0"/>
  </joint>



  <link name="vertical_link7">
    <inertial>
      <origin rpy="0 0 0" xyz="0.002284 -4.1e-05 0.025165"/>
      <mass value="0.5"/>
      <inertia ixx="0.073348887" ixy="0.00030338" ixz="0.001918218" iyy="0.250684593" iyz="-7.5402e-05" izz="0.254469458"/>
    </inertial>
  </link>
  <joint name="vertical_joint7" type="prismatic">
    <origin rpy="0 0 0" xyz="0.19 0 @@flipper_radius"/>
    <parent link="front_left_flipper_wheel_link"/>
    <child link="vertical_link7"/>
    <axis xyz="0 0 1"/>
  </joint>
  <link name="horizontal_link7">
    <visual>
      <origin rpy="0 0 0" xyz="0 0 0"/>
      <geometry>
        <box size="0.38 @@wheel_width 0.005"/>
      </geometry>
    </visual>
    <collision>
      <origin rpy="0 0 0" xyz="0 0 0"/>
      <geometry>
        <box size="0.38 @@wheel_width 0.005"/>
      </geometry>
    </collision>
    <inertial>
      <origin rpy="0 0 0" xyz="0.002284 -4.1e-05 0.025165"/>
      <mass value="0.5"/>
      <inertia ixx="0.073348887" ixy="0.00030338" ixz="0.001918218" iyy="0.250684593" iyz="-7.5402e-05" izz="0.254469458"/>
    </inertial>
  </link>
  <joint name="horizontal_joint7" type="prismatic">
    <origin rpy="0 0 0" xyz="0 0 0"/>
    <parent link="vertical_link7"/>
    <child link="horizontal_link7"/>
    <axis xyz="1 0 0"/>
  </joint>

  <link name="vertical_link8">
    <inertial>
      <origin rpy="0 0 0" xyz="0.002284 -4.1e-05 0.025165"/>
      <mass value="0.5"/>
      <inertia ixx="0.073348887" ixy="0.00030338" ixz="0.001918218" iyy="0.250684593" iyz="-7.5402e-05" izz="0.254469458"/>
    </inertial>
  </link>
  <joint name="vertical_joint8" type="prismatic">
    <origin rpy="0 0 0" xyz="0.19 0 @@flipper_radius"/>
    <parent link="front_right_flipper_wheel_link"/>
    <child link="vertical_link8"/>
    <axis xyz="0 0 1"/>
  </joint>
  <link name="horizontal_link8">
    <visual>
      <origin rpy="0 0 0" xyz="0 0 0"/>
      <geometry>
        <box size="0.38 @@wheel_width 0.005"/>
      </geometry>
    </visual>
    <collision>
      <origin rpy="0 0 0" xyz="0 0 0"/>
      <geometry>
        <box size="0.38 @@wheel_width 0.005"/>
      </geometry>
    </collision>
    <inertial>
      <origin rpy="0 0 0" xyz="0.002284 -4.1e-05 0.025165"/>
      <mass value="0.5"/>
      <inertia ixx="0.073348887" ixy="0.00030338" ixz="0.001918218" iyy="0.250684593" iyz="-7.5402e-05" izz="0.254469458"/>
    </inertial>
  </link>
  <joint name="horizontal_joint8" type="prismatic">
    <origin rpy="0 0 0" xyz="0 0 0"/>
    <parent link="vertical_link8"/>
    <child link="horizontal_link8"/>
    <axis xyz="1 0 0"/>
  </joint>

</robot>